Workbook
Name Austria: 'Customer List'!$F$4:$F$31
Name Belgium: 'Customer List'!$B$4:$B$50
Name Country_List: 'Product List'!$A$5:$A$17
Name Emerging_Markets: 'Customer List'!$G$4:$G$60
Name ESS_SPR_Gen2: 'Product List'!$E$5:$E$20
Name ESS_TCL_CI: 'Product List'!$F$5:$F$20
Name ESS_TCL_Res: 'Product List'!$G$5:$G$20
Name France: 'Customer List'!$H$4:$H$80
Name Germany: 'Customer List'!$D$4:$D$120
Name Heat_Pump: 'Product List'!$Q$5:$Q$18
Name Incoterm_List: Incoterm[Incoterm]
Name Incoterm_List: Incoterm[Incoterm]
Name Incoterm_List: Incoterm[Incoterm]
Name Incoterm_List: Incoterm[Incoterm]
Name Incoterm_List: Incoterm[Incoterm]
Name Incoterm_List: Incoterm[Incoterm]
Name Incoterm_List: Incoterm[Incoterm]
Name Incoterm_List: Incoterm[Incoterm]
Name Italy: 'Customer List'!$I$4:$I$300
Name Netherlands: 'Customer List'!$C$4:$C$70
Name Nordic: 'Customer List'!$J$4:$J$20
Name Product_List: 'Product List'!$C$5:$C$19
Name Spain: 'Customer List'!$K$4:$K$120
Name SPR_BC: 'Product List'!$P$5:$P$20
Name SPR_M_Class: 'Product List'!$O$5:$O$20
Name SPR_MAX_P6: 'Product List'!$R$4:$R$20
Name SPR_P_Class: 'Product List'!$I$5:$I$20
Name SPR_P7: 'Product List'!$H$5:$H$20
Name Stage_List: Stage[Stage]
Name Stage_List: Stage[Stage]
Name Stage_List: Stage[Stage]
Name Stage_List: Stage[Stage]
Name Stage_List: Stage[Stage]
Name Stage_List: Stage[Stage]
Name Stage_List: Stage[Stage]
Name Stage_List: Stage[Stage]
Name Switzerland: 'Customer List'!$E$4:$E$15
Name TCL_C2_Series: 'Product List'!$N$5:$N$22
Name TCL_E_Class: 'Product List'!$M$5:$M$20
Name TCL_S_Class: 'Product List'!$J$5:$J$20
Name TCL_T_Class: 'Product List'!$L$5:$L$21
Name TCL_T5_Pro: 'Product List'!$K$5:$K$20
Name UK: 'Customer List'!$L$4:$L$120

Sheet Pivot Weekly report
A1: below Pivot keep for Arleen
A3: Customer name | B3: (全部)
A4: Product Line | B4: (多项)
A5: Stage | B5: (多项)
A7: 行标签 | B7: Sum of 26M04 | C7: Sum of 26M05 | D7: Sum of 26M06 | E7: 求和项:26M07 | F7: 求和项:26M08 | G7: 求和项:26M09 | H7: 求和项:26M10 | I7: 求和项:26M11 | J7: 求和项:26M12
A8: Benelux Region | B8: 1.27 | C8: 4.11 | D8: 8.14 | E8: 4.46 | F8: 2.84 | G8: 11 | H8: 9.2 | I8: 7.2 | J8: 7.2
A9: Central and Eastern Europe Region | B9: 14 | C9: 17.5 | D9: 15 | E9: 8.8 | F9: 8 | G9: 9 | H9: 17 | I9: 9
A10: France and Switzerland Region | B10: 18.429 | C10: 14 | D10: 14.8 | E10: 16.3 | F10: 13.522 | G10: 11.416 | H10: 10.67 | I10: 10.67 | J10: 10.67
A11: DACH Region | B11: 39 | C11: 21.4 | D11: 21 | E11: 19.2 | F11: 1.35 | G11: 44.6 | H11: 49.9 | I11: 61.75 | J11: 21.35
A12: Italy Region | B12: 19 | C12: 49 | D12: 36 | E12: 47 | F12: 11.6 | G12: 71 | H12: 34 | I12: 54 | J12: 17
A13: Southern Europe Region | B13: 8 | C13: 9 | D13: 9 | E13: 5.3 | F13: 8.4 | G13: 8.6 | H13: 7 | I13: 26.2 | J13: 4.4
A14: Nordics Region | B14: 6.4 | C14: 2.8 | D14: 2.4 | E14: 0.8 | F14: 2 | G14: 16.8 | H14: 12.6 | I14: 10
A15: UK Region | B15: 8.318 | C15: 11.091 | D15: 10.113 | E15: 21.081 | F15: 8.861 | G15: 11.811 | H15: 11.741 | I15: 15.102 | J15: 3.874
A16: #N/A | E16: 2.6 | F16: 2.6 | G16: 2.6 | H16: 0.5 | I16: 0.5 | J16: 0.5
A17: 总计 | B17: 114.417 | C17: 128.901 | D17: 116.453 | E17: 125.541 | F17: 59.173 | G17: 186.827 | H17: 152.611 | I17: 194.422 | J17: 64.994
A20: below Pivot keep for Arleen
A24: Customer name | B24: (全部)
A25: Product Line | B25: (多项)
A26: Stage | B26: (多项)
A28: 行标签 | B28: Sum of 26M04 | C28: Sum of 26M05 | D28: Sum of 26M06 | E28: 求和项:26M07 | F28: 求和项:26M08 | G28: 求和项:26M09 | H28: 求和项:26M10 | I28: 求和项:26M11 | J28: 求和项:26M12
A29: Benelux Region | B29: 0.42 | C29: 1.32 | D29: 0.42 | E29: 0.92 | F29: 0.1 | G29: 1.92 | H29: 2.5 | I29: 3.9 | J29: 3.8
A30: Central and Eastern Europe Region | C30: 3.5
A31: France and Switzerland Region | B31: 3.2 | C31: 1.9 | D31: 4.15 | E31: 3.057 | F31: 3.2 | G31: 3.479 | H31: 2.197 | I31: 1.7 | J31: 2.55
A32: DACH Region | B32: 6.490848 | C32: 4.7761 | D32: 5.53603 | E32: 2.6311 | F32: 3.629538 | G32: 5.56265 | H32: 5.73455 | I32: 7.736228 | J32: 2.89428
A33: Italy Region | B33: 17 | C33: 17 | D33: 19 | E33: 16 | F33: 11 | G33: 22 | H33: 22 | I33: 22 | J33: 18
A34: Southern Europe Region | B34: 1.05 | C34: 2.2 | D34: 2.6 | E34: 2.5 | F34: 0.9 | G34: 3.2 | H34: 2.8 | I34: 3.6 | J34: 2.2
A35: Nordics Region | C35: 0.2 | E35: 1 | H35: 1.2
A36: UK Region | B36: 6.5184 | C36: 7.548 | D36: 3.461 | E36: 3.692 | F36: 2.313 | G36: 4.303 | H36: 2.091 | I36: 2.679 | J36: 1.561
A37: #N/A | B37: 0.4 | C37: 0 | D37: 0.4 | E37: 0.8 | F37: 0.8 | G37: 0.8 | H37: 0.5 | I37: 0.5 | J37: 0.5
A38: 总计 | B38: 35.079248 | C38: 38.4441 | D38: 35.56703 | E38: 30.6001 | F38: 21.942538 | G38: 41.26465 | H38: 39.02255 | I38: 42.115228 | J38: 31.50528
A44: below Pivot keep for Arleen
A46: Customer name | B46: (全部)
A47: Product Line | B47: (多项)
A48: Stage | B48: (多项)
A49: Product Category | B49: ESS
A50: Model name | B50: (多项)
A52: 行标签 | B52: 求和项:26M07 | C52: 求和项:26M08 | D52: 求和项:26M09 | E52: 求和项:26M10 | F52: 求和项:26M11 | G52: 求和项:26M12
A53: Spain | B53: 70 | C53: 35 | D53: 70 | E53: 75 | F53: 75 | G53: 30
A54: France | B54: 128 | C54: 61 | D54: 91 | E54: 93 | F54: 103 | G54: 87
A55: Italy | B55: 650 | C55: 320 | D55: 630 | E55: 540 | F55: 650 | G55: 740
...

Sheet Fcst Accuracy data
A1: Country | B1: Sales Team.Region | C1: Product Category | D1: Attribute | E1: Fcst unweighted | F1: Fcst weighted
C2: PV | D2: 2026-04 | E2: 0.4 | F2: 0.28
C3: PV | D3: 2026-05 | E3: 0 | F3: 0
C4: PV | D4: 2026-06 | E4: 0.4 | F4: 0.28
C5: PV | D5: 2026-07 | E5: 3.4 | F5: 2.38
C6: PV | D6: 2026-08 | E6: 3.4 | F6: 2.38
C7: PV | D7: 2026-09 | E7: 3.4 | F7: 2.38
C8: PV | D8: 2026-10 | E8: 1 | F8: 0.7
C9: PV | D9: 2026-11 | E9: 1 | F9: 0.7
C10: PV | D10: 2026-12 | E10: 1 | F10: 0.7
A11: Belgium | B11: Benelux Region | C11: PV | D11: 2026-05 | E11: 3.38 | F11: 3.38
A12: Belgium | B12: Benelux Region | C12: PV | D12: 2026-06 | E12: 6.46 | F12: 6.46
A13: Belgium | B13: Benelux Region | C13: PV | D13: 2026-07 | E13: 4.06 | F13: 4.06
A14: Belgium | B14: Benelux Region | C14: PV | D14: 2026-08 | E14: 2.94 | F14: 2.94
A15: Belgium | B15: Benelux Region | C15: PV | D15: 2026-09 | E15: 11.72 | F15: 8.98
A16: Belgium | B16: Benelux Region | C16: PV | D16: 2026-10 | E16: 6.1 | F16: 3.45
A17: Belgium | B17: Benelux Region | C17: PV | D17: 2026-11 | E17: 5.5 | F17: 2.02
A18: Belgium | B18: Benelux Region | C18: PV | D18: 2026-12 | E18: 5.4 | F18: 1.92
A19: Belgium | B19: Benelux Region | C19: PV | D19: 2026-04 | E19: 0.84 | F19: 0.84
A20: Croatia | B20: Central and Eastern Europe Region | C20: PV | D20: 2026-05 | E20: 1.2 | F20: 1.2
A21: Cyprus | B21: Southern Europe Region | C21: PV | D21: 2026-09 | E21: 1 | F21: 0.3
A22: France | B22: France and Switzerland Region | C22: PV | D22: 2026-04 | E22: 21.629 | F22: 15.9461
... A146: italy | B146: Italy Region | C146: PV | D146: 2026-12 | E146: 5 | F146: 1.5

Sheet Conso
A1: Country | B1: Customer name | C1: RSM | D1: Product Line | E1: Model name | F1: Stage | G1: Comments (Deal Breaker, spec/requirements, etc) | H1: Supply Chain | I1: 26M04 | J1: 26M05 | K1: 26M06 | L1: 26M07 | M1: 26M08 | N1: 26M09 | O1: 26M10 | P1: 26M11 | Q1: 26M12 | R1: 27M01 | S1: 27M02 | T1: 27M03 | U1: 27M04 | V1: 27M05 | W1: 27M06 | X1: Product Category | Y1: Region | Z1: Sales Team | AA1: Product Conso
B2: Solarmarkt | C2: Manu | D2: TCL_C2_Series | E2: HSM-BE54-JD485/490 | F2: 2 - Initial offer | G2: Amarenco // CFP, 470W, CFP PPE2 V1<550 // | H2: EU | Q2: 0.4 | X2: PV | Y2: =VLOOKUP(Conso_FCST[[#This Row],[Country]],'Country-Region'!A:D,4,0) -> #N/A | Z2: =VLOOKUP(Conso_FCST[[#This Row],[Country]],'Country-Region'!A:D,3,0) -> #N/A | AA2: =IFERROR(VLOOKUP(Conso_FCST[[#This Row],[Model name]],Prod_T6[[#All],[Model name]:[Product Conso]],2,0),"exclude") -> HSM-BE54-JD
B3: Solarmarkt | C3: Manu | D3: SPR_P7 | E3: P7-BLK-2mm-460 | F3: 5 - Finalize contract | H3: EU | I3: 0.2 | J3: 0 | K3: 0.2 | L3: 0.4 | M3: 0.4 | N3: 0.4 | O3: 0.1 | P3: 0.1 | Q3: 0.1 | X3: PV | Y3: =VLOOKUP(Conso_FCST[[#This Row],[Country]],'Country-Region'!A:D,4,0) -> #N/A | Z3: =VLOOKUP(Conso_FCST[[#This Row],[Country]],'Country-Region'!A:D,3,0) -> #N/A | AA3: =IFERROR(VLOOKUP(Conso_FCST[[#This Row],[Model name]],Prod_T6[[#All],[Model name]:[Product Conso]],2,0),"exclude") -> P7 RES BLK 2.0
B4: Solarmarkt | C4: Manu | D4: TCL_T_Class | E4: HSM-ND54-DR500 | F4: 5 - Finalize contract | H4: EU | L4: 1.3 | M4: 1.3 | N4: 1.3 | O4: 0.1 | P4: 0.1 | Q4: 0.1 | X4: PV | Y4: =VLOOKUP(Conso_FCST[[#This Row],[Country]],'Country-Region'!A:D,4,0) -> #N/A | Z4: =VLOOKUP(Conso_FCST[[#This Row],[Country]],'Country-Region'!A:D,3,0) -> #N/A | AA4: =IFERROR(VLOOKUP(Conso_FCST[[#This Row],[Model name]],Prod_T6[[#All],[Model name]:[Product Conso]],2,0),"exclude") -> HSM-ND54-DR
B5: Solexis | C5: Manu | D5: SPR_P7 | E5: P7-BLK-P-510 | F5: 5 - Finalize contract | H5: EU | I5: 0.2 | J5: 0 | K5: 0.2 | L5: 0.4 | M5: 0.4 | N5: 0.4 | O5: 0.4 | P5: 0.4 | Q5: 0.4 | X5: PV | Y5: =VLOOKUP(Conso_FCST[[#This Row],[Country]],'Country-Region'!A:D,4,0) -> #N/A | Z5: =VLOOKUP(Conso_FCST[[#This Row],[Country]],'Country-Region'!A:D,3,0) -> #N/A | AA5: =IFERROR(VLOOKUP(Conso_FCST[[#This Row],[Model name]],Prod_T6[[#All],[Model name]:[Product Conso]],2,0),"exclude") -> P7 RES BLK-P
B6: Solexis | C6: Manu | D6: TCL_T_Class | E6: HSM-ND54-DR500 | F6: 5 - Finalize contract | H6: EU | L6: 1.3 | M6: 1.3 | N6: 1.3 | O6: 0.4 | P6: 0.4 | Q6: 0.4 | X6: PV | Y6: =VLOOKUP(Conso_FCST[[#This Row],[Country]],'Country-Region'!A:D,4,0) -> #N/A | Z6: =VLOOKUP(Conso_FCST[[#This Row],[Country]],'Country-Region'!A:D,3,0) -> #N/A | AA6: =IFERROR(VLOOKUP(Conso_FCST[[#This Row],[Model name]],Prod_T6[[#All],[Model name]:[Product Conso]],2,0),"exclude") -> HSM-ND54-DR
A7: 0.1 | B7: Solexis | C7: Manu | D7: TCL_C2_Series | E7: HSM-BE54-JD485/490 | F7: 2 - Initial offer | G7: Amarenco // CFP, 470W, CFP PPE2 V1<550 // | H7: EU | Q7: 0.4 | X7: PV | Y7: =VLOOKUP(Conso_FCST[[#This Row],[Country]],'Country-Region'!A:D,4,0) -> #N/A | Z7: =VLOOKUP(Conso_FCST[[#This Row],[Country]],'Country-Region'!A:D,3,0) -> #N/A | AA7: =IFERROR(VLOOKUP(Conso_FCST[[#This Row],[Model name]],Prod_T6[[#All],[Model name]:[Product Conso]],2,0),"exclude") -> HSM-BE54-JD
A8: Austria | B8: Wien Energie | D8: TCL_T_Class | E8: HSM-ND66-GK725 | F8: 2 - Initial offer | H8: EU | X8: PV | Y8: =VLOOKUP(Conso_FCST[[#This Row],[Country]],'Country-Region'!A:D,4,0) -> DACH Region | Z8: =VLOOKUP(Conso_FCST[[#This Row],[Country]],'Country-Region'!A:D,3,0) -> Germany | AA8: =IFERROR(VLOOKUP(Conso_FCST[[#This Row],[Model name]],Prod_T6[[#All],[Model name]:[Product Conso]],2,0),"exclude") -> HSM-ND66-GK
A9: Belgium | B9: ECOSTAL SPRL | C9: Romain | D9: TCL_T_Class | E9: HSM-ND48-DR450 | F9: 7 - Booked | G9: BOOKED | H9: Offshore | J9: 0.84 | K9: 0.84 | L9: 0.84 | M9: 0.84 | X9: PV | Y9: =VLOOKUP(Conso_FCST[[#This Row],[Country]],'Country-Region'!A:D,4,0) -> Benelux Region | Z9: =VLOOKUP(Conso_FCST[[#This Row],[Country]],'Country-Region'!A:D,3,0) -> BeNeLux | AA9: =IFERROR(VLOOKUP(Conso_FCST[[#This Row],[Model name]],Prod_T6[[#All],[Model name]:[Product Conso]],2,0),"exclude") -> HSM-ND48-DR
A10: Belgium | B10: bvba BeliVert | D10: SPR_BC | E10: SPR-BE54-HD490/495 | F10: 3 - Negotiation | H10: EU | P10: 0.9 | Q10: 0.9 | X10: PV | Y10: =VLOOKUP(Conso_FCST[[#This Row],[Country]],'Country-Region'!A:D,4,0) -> Benelux Region | Z10: =VLOOKUP(Conso_FCST[[#This Row],[Country]],'Country-Region'!A:D,3,0) -> BeNeLux | AA10: =IFERROR(VLOOKUP(Conso_FCST[[#This Row],[Model name]],Prod_T6[[#All],[Model name]:[Product Conso]],2,0),"exclude") -> SPR-BE54-HD
A11: Belgium | B11: SOLARPRO BVBA | C11: Regis | D11: SPR_P7 | E11: P7-BLK-2mm-460 | F11: 7 - Booked | H11: EU | J11: 0.1 | L11: 0.1 | M11: 0.1 | N11: 0.1 | X11: PV | Y11: =VLOOKUP(Conso_FCST[[#This Row],[Country]],'Country-Region'!A:D,4,0) -> Benelux Region | Z11: =VLOOKUP(Conso_FCST[[#This Row],[Country]],'Country-Region'!A:D,3,0) -> BeNeLux | AA11: =IFERROR(VLOOKUP(Conso_FCST[[#This Row],[Model name]],Prod_T6[[#All],[Model name]:[Product Conso]],2,0),"exclude") -> P7 RES BLK 2.0
A12: Belgium | B12: SOLARPRO | D12: SPR_BC | E12: SPR-BE54-HD490/495 | F12: 3 - Negotiation | H12: EU | O12: 0.2 | P12: 0.2 | Q12: 0.2 | X12: PV | Y12: =VLOOKUP(Conso_FCST[[#This Row],[Country]],'Country-Region'!A:D,4,0) -> Benelux Region | Z12: =VLOOKUP(Conso_FCST[[#This Row],[Country]],'Country-Region'!A:D,3,0) -> BeNeLux | AA12: =IFERROR(VLOOKUP(Conso_FCST[[#This Row],[Model name]],Prod_T6[[#All],[Model name]:[Product Conso]],2,0),"exclude") -> SPR-BE54-HD
A13: Belgium | B13: Reno.Energy SA | D13: ESS_TCL_CI | E13: BlueArk W10-125K-261 | F13: 2 - Initial offer | G13: AWAITING FEEDBACK NEW ASP | H13: EU | O13: 1 | P13: 1 | Q13: 1 | X13: ESS | Y13: =VLOOKUP(Conso_FCST[[#This Row],[Country]],'Country-Region'!A:D,4,0) -> Benelux Region | Z13: =VLOOKUP(Conso_FCST[[#This Row],[Country]],'Country-Region'!A:D,3,0) -> BeNeLux | AA13: =IFERROR(VLOOKUP(Conso_FCST[[#This Row],[Model name]],Prod_T6[[#All],[Model name]:[Product Conso]],2,0),"exclude") -> BlueArk W10-125K-261
A14: Belgium | B14: RENA SOLAR & CHARGE | D14: TCL_C2_Series | E14: SPR-BE54-HD490/495 | F14: 3 - Negotiation | H14: EU | O14: 0.1 | P14: 0.1 | Q14: 0.1 | X14: PV | Y14: =VLOOKUP(Conso_FCST[[#This Row],[Country]],'Country-Region'!A:D,4,0) -> Benelux Region | Z14: =VLOOKUP(Conso_FCST[[#This Row],[Country]],'Country-Region'!A:D,3,0) -> BeNeLux | AA14: =IFERROR(VLOOKUP(Conso_FCST[[#This Row],[Model name]],Prod_T6[[#All],[Model name]:[Product Conso]],2,0),"exclude") -> SPR-BE54-HD
A15: Belgium | B15: Neopower | C15: Romain | D15: SPR_P7 | E15: P7-BLK-2mm-460 | F15: 7 - Booked | H15: EU | J15: 0.1 | L15: 0.1 | N15: 0.1 | X15: PV | Y15: =VLOOKUP(Conso_FCST[[#This Row],[Country]],'Country-Region'!A:D,4,0) -> Benelux Region | Z15: =VLOOKUP(Conso_FCST[[#This Row],[Country]],'Country-Region'!A:D,3,0) -> BeNeLux | AA15: =IFERROR(VLOOKUP(Conso_FCST[[#This Row],[Model name]],Prod_T6[[#All],[Model name]:[Product Conso]],2,0),"exclude") -> P7 RES BLK 2.0
A16: Belgium | B16: bvba BeliVert | C16: Regis | D16: SPR_P7 | E16: P7-BLK-2mm-455 | F16: 7 - Booked | G16: AWAITING ORDER | H16: EU | I16: 0.42 | J16: 0.42 | K16: 0.42 | L16: 0.42 | N16: 0.42 | X16: PV | Y16: =VLOOKUP(Conso_FCST[[#This Row],[Country]],'Country-Region'!A:D,4,0) -> Benelux Region | Z16: =VLOOKUP(Conso_FCST[[#This Row],[Country]],'Country-Region'!A:D,3,0) -> BeNeLux | AA16: =IFERROR(VLOOKUP(Conso_FCST[[#This Row],[Model name]],Prod_T6[[#All],[Model name]:[Product Conso]],2,0),"exclude") -> P7 RES BLK 2.0
A17: Belgium | B17: Neopower | D17: SPR_BC | E17: SPR-BE54-HD490/495 | F17: 3 - Negotiation | H17: EU | O17: 0.1 | P17: 0.1 | Q17: 0.1 | X17: PV | Y17: =VLOOKUP(Conso_FCST[[#This Row],[Country]],'Country-Region'!A:D,4,0) -> Benelux Region | Z17: =VLOOKUP(Conso_FCST[[#This Row],[Country]],'Country-Region'!A:D,3,0) -> BeNeLux | AA17: =IFERROR(VLOOKUP(Conso_FCST[[#This Row],[Model name]],Prod_T6[[#All],[Model name]:[Product Conso]],2,0),"exclude") -> SPR-BE54-HD
A18: Belgium | B18: ENR Lux | D18: SPR_BC | E18: SPR-BE54-HD490/495 | F18: 7 - Booked | H18: EU | O18: 0.2 | P18: 0.2 | Q18: 0.2 | X18: PV | Y18: =VLOOKUP(Conso_FCST[[#This Row],[Country]],'Country-Region'!A:D,4,0) -> Benelux Region | Z18: =VLOOKUP(Conso_FCST[[#This Row],[Country]],'Country-Region'!A:D,3,0) -> BeNeLux | AA18: =IFERROR(VLOOKUP(Conso_FCST[[#This Row],[Model name]],Prod_T6[[#All],[Model name]:[Product Conso]],2,0),"exclude") -> SPR-BE54-HD
A19: Belgium | B19: MR group | D19: TCL_T5_Pro | E19: HSM-NT60-GH 580/585 | F19: 2 - Initial offer | H19: EU | O19: 0.9 | P19: 0.9 | Q19: 0.9 | X19: PV | Y19: =VLOOKUP(Conso_FCST[[#This Row],[Country]],'Country-Region'!A:D,4,0) -> Benelux Region | Z19: =VLOOKUP(Conso_FCST[[#This Row],[Country]],'Country-Region'!A:D,3,0) -> BeNeLux | AA19: =IFERROR(VLOOKUP(Conso_FCST[[#This Row],[Model name]],Prod_T6[[#All],[Model name]:[Product Conso]],2,0),"exclude") -> HSM-NT60-GH
A20: Belgium | B20: MR group | D20: TCL_C2_Series | E20: SPR-BE54-HD490/495 | F20: 3 - Negotiation | H20: EU | N20: 0.9 | O20: 0.9 | P20: 0.9 | Q20: 0.9 | X20: PV | Y20: =VLOOKUP(Conso_FCST[[#This Row],[Country]],'Country-Region'!A:D,4,0) -> Benelux Region | Z20: =VLOOKUP(Conso_FCST[[#This Row],[Country]],'Country-Region'!A:D,3,0) -> BeNeLux | AA20: =IFERROR(VLOOKUP(Conso_FCST[[#This Row],[Model name]],Prod_T6[[#All],[Model name]:[Product Conso]],2,0),"exclude") -> SPR-BE54-HD
A21: Belgium | B21: ECOSTAL SPRL | D21: ESS_TCL_CI | E21: BlueArk X5-50K-100 | F21: 2 - Initial offer | G21: AWAITING FEEDBACK NEW ASP | H21: Offshore | O21: 2 | P21: 2 | Q21: 2 | X21: ESS | Y21: =VLOOKUP(Conso_FCST[[#This Row],[Country]],'Country-Region'!A:D,4,0) -> Benelux Region | Z21: =VLOOKUP(Conso_FCST[[#This Row],[Country]],'Country-Region'!A:D,3,0) -> BeNeLux | AA21: =IFERROR(VLOOKUP(Conso_FCST[[#This Row],[Model name]],Prod_T6[[#All],[Model name]:[Product Conso]],2,0),"exclude") -> BlueArk X5-50K-100
A22: Belgium | B22: ECOSTAL SPRL | D22: ESS_TCL_CI | E22: BlueArk W10-125K-261 | F22: 2 - Initial offer | G22: AWAITING FEEDBACK NEW ASP | H22: Offshore | O22: 2 | P22: 3 | Q22: 3 | X22: ESS | Y22: =VLOOKUP(Conso_FCST[[#This Row],[Country]],'Country-Region'!A:D,4,0) -> Benelux Region | Z22: =VLOOKUP(Conso_FCST[[#This Row],[Country]],'Country-Region'!A:D,3,0) -> BeNeLux | AA22: =IFERROR(VLOOKUP(Conso_FCST[[#This Row],[Model name]],Prod_T6[[#All],[Model name]:[Product Conso]],2,0),"exclude") -> BlueArk W10-125K-261
A23: Belgium | B23: Reno.Energy SA | D23: ESS_TCL_CI | E23: BlueArk X5-50K-100 | F23: 2 - Initial offer | G23: AWAITING FEEDBACK NEW ASP | H23: EU | O23: 1 | P23: 1 | Q23: 1 | X23: ESS | Y23: =VLOOKUP(Conso_FCST[[#This Row],[Country]],'Country-Region'!A:D,4,0) -> Benelux Region | Z23: =VLOOKUP(Conso_FCST[[#This Row],[Country]],'Country-Region'!A:D,3,0) -> BeNeLux | AA23: =IFERROR(VLOOKUP(Conso_FCST[[#This Row],[Model name]],Prod_T6[[#All],[Model name]:[Product Conso]],2,0),"exclude") -> BlueArk X5-50K-100
A24: Belgium | B24: ENR Lux | D24: SPR_P7 | E24: P7-BLK-2mm-460 | F24: 7 - Booked | H24: EU | J24: 0.2 | L24: 0.2 | N24: 0.2 | X24: PV | Y24: =VLOOKUP(Conso_FCST[[#This Row],[Country]],'Country-Region'!A:D,4,0) -> Benelux Region | Z24: =VLOOKUP(Conso_FCST[[#This Row],[Country]],'Country-Region'!A:D,3,0) -> BeNeLux | AA24: =IFERROR(VLOOKUP(Conso_FCST[[#This Row],[Model name]],Prod_T6[[#All],[Model name]:[Product Conso]],2,0),"exclude") -> P7 RES BLK 2.0
A25: Belgium | B25: Reno.Energy SA | D25: SPR_BC | E25: SPR-BE54-HD490/495 | F25: 3 - Negotiation | G25: AWAITING FORECAST | H25: EU | N25: 1 | X25: PV | Y25: =VLOOKUP(Conso_FCST[[#This Row],[Country]],'Country-Region'!A:D,4,0) -> Benelux Region | Z25: =VLOOKUP(Conso_FCST[[#This Row],[Country]],'Country-Region'!A:D,3,0) -> BeNeLux | AA25: =IFERROR(VLOOKUP(Conso_FCST[[#This Row],[Model name]],Prod_T6[[#All],[Model name]:[Product Conso]],2,0),"exclude") -> SPR-BE54-HD
A26: Belgium | B26: RENA SOLAR & CHARGE | C26: Regis | D26: SPR_P7 | E26: P7-BLK-2mm-460 | F26: 7 - Booked | H26: EU | J26: 0.1 | L26: 0.1 | N26: 0.1 | P26: 0.1 | X26: PV | Y26: =VLOOKUP(Conso_FCST[[#This Row],[Country]],'Country-Region'!A:D,4,0) -> Benelux Region | Z26: =VLOOKUP(Conso_FCST[[#This Row],[Country]],'Country-Region'!A:D,3,0) -> BeNeLux | AA26: =IFERROR(VLOOKUP(Conso_FCST[[#This Row],[Model name]],Prod_T6[[#All],[Model name]:[Product Conso]],2,0),"exclude") -> P7 RES BLK 2.0
A27: Belgium | B27: Reno.Energy SA | D27: TCL_T5_Pro | E27: HSM-NT48-HH 465/470-Black | F27: 3 - Negotiation | G27: AWAITING FORECAST | H27: EU | N27: 0.8 | O27: 0.8 | P27: 0.8 | Q27: 0.8 | X27: PV | Y27: =VLOOKUP(Conso_FCST[[#This Row],[Country]],'Country-Region'!A:D,4,0) -> Benelux Region | Z27: =VLOOKUP(Conso_FCST[[#This Row],[Country]],'Country-Region'!A:D,3,0) -> BeNeLux | AA27: =IFERROR(VLOOKUP(Conso_FCST[[#This Row],[Model name]],Prod_T6[[#All],[Model name]:[Product Conso]],2,0),"exclude") -> HSM-NT48-HH
A28: Belgium | B28: Reno.Energy SA | D28: TCL_C2_Series | E28: HSM-BE54-HD485/490 | F28: 3 - Negotiation | G28: AWAITING FORECAST | H28: EU | N28: 0.4 | O28: 0.4 | P28: 0.4 | Q28: 0.4 | X28: PV | Y28: =VLOOKUP(Conso_FCST[[#This Row],[Country]],'Country-Region'!A:D,4,0) -> Benelux Region | Z28: =VLOOKUP(Conso_FCST[[#This Row],[Country]],'Country-Region'!A:D,3,0) -> BeNeLux | AA28: =IFERROR(VLOOKUP(Conso_FCST[[#This Row],[Model name]],Prod_T6[[#All],[Model name]:[Product Conso]],2,0),"exclude") -> HSM-BE54-HD
A29: Belgium | B29: ECOSTAL SPRL | D29: SPR_BC | E29: SPR-BE54-HD490/495 | F29: 4 - BAFO | G29: AWAITING FORECAST | H29: Offshore | P29: 0.4 | Q29: 0.4 | X29: PV | Y29: =VLOOKUP(Conso_FCST[[#This Row],[Country]],'Country-Region'!A:D,4,0) -> Benelux Region | Z29: =VLOOKUP(Conso_FCST[[#This Row],[Country]],'Country-Region'!A:D,3,0) -> BeNeLux | AA29: =IFERROR(VLOOKUP(Conso_FCST[[#This Row],[Model name]],Prod_T6[[#All],[Model name]:[Product Conso]],2,0),"exclude") -> SPR-BE54-HD
A30: Belgium | B30: ECOSTAL SPRL | D30: TCL_T5_Pro | E30: HSM-NT66-GH 640/645 | F30: 4 - BAFO | G30: AWAITING FORECAST | H30: Offshore | O30: 0.4 | P30: 0.4 | Q30: 0.4 | X30: PV | Y30: =VLOOKUP(Conso_FCST[[#This Row],[Country]],'Country-Region'!A:D,4,0) -> Benelux Region | Z30: =VLOOKUP(Conso_FCST[[#This Row],[Country]],'Country-Region'!A:D,3,0) -> BeNeLux | AA30: =IFERROR(VLOOKUP(Conso_FCST[[#This Row],[Model name]],Prod_T6[[#All],[Model name]:[Product Conso]],2,0),"exclude") -> HSM-NT66-GH
A31: Belgium | B31: ECOSTAL SPRL | C31: Romain | D31: TCL_T_Class | E31: HSM-ND66-GK725 | F31: 6 - Won | G31: WON | H31: Offshore | N31: 5.7 | X31: PV | Y31: =VLOOKUP(Conso_FCST[[#This Row],[Country]],'Country-Region'!A:D,4,0) -> Benelux Region | Z31: =VLOOKUP(Conso_FCST[[#This Row],[Country]],'Country-Region'!A:D,3,0) -> BeNeLux | AA31: =IFERROR(VLOOKUP(Conso_FCST[[#This Row],[Model name]],Prod_T6[[#All],[Model name]:[Product Conso]],2,0),"exclude") -> HSM-ND66-GK
A32: Belgium | B32: SOLAR DEPOT SARL. | C32: Romain | D32: TCL_T_Class | E32: HSM-ND48-DR455 | F32: 7 - Booked | G32: AWAITING ORDER | H32: EU | I32: 0.42 | X32: PV | Y32: =VLOOKUP(Conso_FCST[[#This Row],[Country]],'Country-Region'!A:D,4,0) -> Benelux Region | Z32: =VLOOKUP(Conso_FCST[[#This Row],[Country]],'Country-Region'!A:D,3,0) -> BeNeLux | AA32: =IFERROR(VLOOKUP(Conso_FCST[[#This Row],[Model name]],Prod_T6[[#All],[Model name]:[Product Conso]],2,0),"exclude") -> HSM-ND48-DR
A33: Belgium | B33: ECOSTAL SPRL | D33: TCL_T_Class | E33: HSM-ND54-DR505 | F33: 7 - Booked | G33: Q1 PROJECT | H33: Offshore | J33: 1.2 | K33: 1.2 | X33: PV | Y33: =VLOOKUP(Conso_FCST[[#This Row],[Country]],'Country-Region'!A:D,4,0) -> Benelux Region | Z33: =VLOOKUP(Conso_FCST[[#This Row],[Country]],'Country-Region'!A:D,3,0) -> BeNeLux | AA33: =IFERROR(VLOOKUP(Conso_FCST[[#This Row],[Model name]],Prod_T6[[#All],[Model name]:[Product Conso]],2,0),"exclude") -> HSM-ND54-DR
A34: Belgium | B34: ECOSTAL SPRL | D34: TCL_C2_Series | E34: HSM-BE54-HD485/490 | F34: 3 - Negotiation | G34: AWAITING FORECAST | H34: offshore | O34: 1 | P34: 1 | Q34: 1 | X34: PV | Y34: =VLOOKUP(Conso_FCST[[#This Row],[Country]],'Country-Region'!A:D,4,0) -> Benelux Region | Z34: =VLOOKUP(Conso_FCST[[#This Row],[Country]],'Country-Region'!A:D,3,0) -> BeNeLux | AA34: =IFERROR(VLOOKUP(Conso_FCST[[#This Row],[Model name]],Prod_T6[[#All],[Model name]:[Product Conso]],2,0),"exclude") -> HSM-BE54-HD
A35: Belgium | B35: ECOSTAL SPRL | D35: TCL_T5_Pro | E35: HSM-NT48-HH 465/470-Black | F35: 7 - Booked | G35: BOOKED | H35: Offshore | M35: 2 | N35: 2 | O35: 2 | X35: PV | Y35: =VLOOKUP(Conso_FCST[[#This Row],[Country]],'Country-Region'!A:D,4,0) -> Benelux Region | Z35: =VLOOKUP(Conso_FCST[[#This Row],[Country]],'Country-Region'!A:D,3,0) -> BeNeLux | AA35: =IFERROR(VLOOKUP(Conso_FCST[[#This Row],[Model name]],Prod_T6[[#All],[Model name]:[Product Conso]],2,0),"exclude") -> HSM-NT48-HH
A36: Belgium | B36: ECOSTAL SPRL | D36: TCL_T_Class | E36: HSM-ND48-DR450 | F36: 7 - Booked | G36: H1-2026 | H36: Offshore | J36: 0.42 | K36: 4 | L36: 2.3 | X36: PV | Y36: =VLOOKUP(Conso_FCST[[#This Row],[Country]],'Country-Region'!A:D,4,0) -> Benelux Region | Z36: =VLOOKUP(Conso_FCST[[#This Row],[Country]],'Country-Region'!A:D,3,0) -> BeNeLux | AA36: =IFERROR(VLOOKUP(Conso_FCST[[#This Row],[Model name]],Prod_T6[[#All],[Model name]:[Product Conso]],2,0),"exclude") -> HSM-ND48-DR
A37: Belgium | B37: SOLAR DEPOT SARL. | D37: TCL_T5_Pro | E37: HSM-NT48-HH 465/470-Black | F37: 7 - Booked | H37: EU | X37: PV | Y37: =VLOOKUP(Conso_FCST[[#This Row],[Country]],'Country-Region'!A:D,4,0) -> Benelux Region | Z37: =VLOOKUP(Conso_FCST[[#This Row],[Country]],'Country-Region'!A:D,3,0) -> BeNeLux | AA37: =IFERROR(VLOOKUP(Conso_FCST[[#This Row],[Model name]],Prod_T6[[#All],[Model name]:[Product Conso]],2,0),"exclude") -> HSM-NT48-HH
A38: Bulgaria | B38: New customer | D38: TCL_T_Class | E38: HSM-ND66-GR625 | F38: 2 - Initial offer | G38: 2 containers CIF Thessaloniki | H38: Offshore | L38: 0.8 | X38: PV | Y38: =VLOOKUP(Conso_FCST[[#This Row],[Country]],'Country-Region'!A:D,4,0) -> Southern Europe Region | Z38: =VLOOKUP(Conso_FCST[[#This Row],[Country]],'Country-Region'!A:D,3,0) -> Southern Europe Region | AA38: =IFERROR(VLOOKUP(Conso_FCST[[#This Row],[Model name]],Prod_T6[[#All],[Model name]:[Product Conso]],2,0),"exclude") -> HSM-ND66-GR
A39: Bulgaria | B39: New customer | D39: TCL_T_Class | E39: HSM-ND48-DR450 | F39: 2 - Initial offer | G39: 2 containers CIF Thessaloniki | H39: Offshore | L39: 0.8 | X39: PV | Y39: =VLOOKUP(Conso_FCST[[#This Row],[Country]],'Country-Region'!A:D,4,0) -> Southern Europe Region | Z39: =VLOOKUP(Conso_FCST[[#This Row],[Country]],'Country-Region'!A:D,3,0) -> Southern Europe Region | AA39: =IFERROR(VLOOKUP(Conso_FCST[[#This Row],[Model name]],Prod_T6[[#All],[Model name]:[Product Conso]],2,0),"exclude") -> HSM-ND48-DR
A40: Croatia | B40: Mobis | D40: TCL_T_Class | E40: HSM-ND66-GK725 | F40: 7 - Booked | G40: FCA RTD, 3 containers | H40: Offshore | J40: 1.2 | X40: PV | Y40: =VLOOKUP(Conso_FCST[[#This Row],[Country]],'Country-Region'!A:D,4,0) -> Central and Eastern Europe Region | Z40: =VLOOKUP(Conso_FCST[[#This Row],[Country]],'Country-Region'!A:D,3,0) -> C&E EU | AA40: =IFERROR(VLOOKUP(Conso_FCST[[#This Row],[Model name]],Prod_T6[[#All],[Model name]:[Product Conso]],2,0),"exclude") -> HSM-ND66-GK
...

Sheet Country-Region
A1: Country | B1: Market Country | C1: Sales Team | D1: Region
A2: Belgium | B2: Belgium | C2: BeNeLux | D2: Benelux Region
A3: Netherlands | B3: Netherlands | C3: BeNeLux | D3: Benelux Region
A4: Czech Republic | B4: C&E EU | C4: C&E EU | D4: Central and Eastern Europe Region
A5: CZ | B5: C&E EU | C5: C&E EU | D5: Central and Eastern Europe Region
A6: Emerging_Markets | B6: C&E EU | C6: C&E EU | D6: Central and Eastern Europe Region
A7: Hungary | B7: C&E EU | C7: C&E EU | D7: Central and Eastern Europe Region
A8: Lithuania | B8: C&E EU | C8: C&E EU | D8: Central and Eastern Europe Region
A9: Poland | B9: C&E EU | C9: C&E EU | D9: Central and Eastern Europe Region
A10: Poland-Jan | B10: C&E EU | C10: C&E EU | D10: Central and Eastern Europe Region
A11: Romania | B11: C&E EU | C11: C&E EU | D11: Central and Eastern Europe Region
A12: Lithiania | B12: C&E EU | C12: C&E EU | D12: Central and Eastern Europe Region
... A33: UK | B33: UK | C33: UK | D33: UK Region

Sheet Instructions
B2: Go to FCST Tab and fill out each line as follow :
B4: Fill information about Customer
B5: 1- Select Country in Column A
B6: 2- Pick customer from List available. It is adjusted per country selected. (see column B)
B7: 3- Other informations (Tier, CL, etc) will populate automatically
B8: 4- For new customer or unspecified, select "New Customer / Balance of others customer"
B9: 5- if critical conditions to meet, use column K "Comments" to specify
B12: Fill information about Product
B13: 1- Select Product Line to differentiate between BTP, Sunpower P7, TCL Solar, etc. It will narrow list of model name. (column D)
B14: 2- Select Model Name in column E
B15: 3- Other customers will be populated automatically
B18: Fill information of Quantity
... B33: Cells to use are in light blue

Sheet Nordic
E1: TCL_T_Class | G1: Category | J1: mw/qty | K1: mw/qty | L1: mw/qty | M1: mw/qty | N1: mw/qty | O1: mw/qty | P1: mw/qty | Q1: mw/qty | R1: mw/qty | S1: mw/qty | T1: mw/qty | U1: mw/qty | V1: mw/qty | W1: mw/qty | X1: mw/qty | Y1: mw/qty | Z1: mw/qty | AA1: mw/qty | AB1: mw/qty | AC1: mw/qty
G2: ESS | J2: {=SUMPRODUCT((Nordics[Product Category]=$G2)*SUBTOTAL(109,OFFSET(INDEX(Nordics[26M04],1),ROW(Nordics[26M04])-MIN(ROW(Nordics[26M04])),0,1)))} -> 0 | K2: {=SUMPRODUCT((Nordics[Product Category]=$G2)*SUBTOTAL(109,OFFSET(INDEX(Nordics[26M05],1),ROW(Nordics[26M05])-MIN(ROW(Nordics[26M05])),0,1)))} -> 0 | L2: {=SUMPRODUCT((Nordics[Product Category]=$G2)*SUBTOTAL(109,OFFSET(INDEX(Nordics[26M06],1),ROW(Nordics[26M06])-MIN(ROW(Nordics[26M06])),0,1)))} -> 0 | M2: {=SUMPRODUCT((Nordics[Product Category]=$G2)*SUBTOTAL(109,OFFSET(INDEX(Nordics[26M07],1),ROW(Nordics[26M07])-MIN(ROW(Nordics[26M07])),0,1)))} -> 0 | N2: {=SUMPRODUCT((Nordics[Product Category]=$G2)*SUBTOTAL(109,OFFSET(INDEX(Nordics[26M08],1),ROW(Nordics[26M08])-MIN(ROW(Nordics[26M08])),0,1)))} -> 0 | O2: {=SUMPRODUCT((Nordics[Product Category]=$G2)*SUBTOTAL(109,OFFSET(INDEX(Nordics[26M09],1),ROW(Nordics[26M09])-MIN(ROW(Nordics[26M09])),0,1)))} -> 2 | P2: {=SUMPRODUCT((Nordics[Product Category]=$G2)*SUBTOTAL(109,OFFSET(INDEX(Nordics[26M10],1),ROW(Nordics[26M10])-MIN(ROW(Nordics[26M10])),0,1)))} -> 0 | Q2: {=SUMPRODUCT((Nordics[Product Category]=$G2)*SUBTOTAL(109,OFFSET(INDEX(Nordics[26M11],1),ROW(Nordics[26M11])-MIN(ROW(Nordics[26M11])),0,1)))} -> 0 | R2: {=SUMPRODUCT((Nordics[Product Category]=$G2)*SUBTOTAL(109,OFFSET(INDEX(Nordics[26M12],1),ROW(Nordics[26M12])-MIN(ROW(Nordics[26M12])),0,1)))} -> 50 | S2: {=SUMPRODUCT((Nordics[Product Category]=$G2)*SUBTOTAL(109,OFFSET(INDEX(Nordics[26Q2],1),ROW(Nordics[26Q2])-MIN(ROW(Nordics[26Q2])),0,1)))} -> 0 | T2: {=SUMPRODUCT((Nordics[Product Category]=$G2)*SUBTOTAL(109,OFFSET(INDEX(Nordics[26Q3],1),ROW(Nordics[26Q3])-MIN(ROW(Nordics[26Q3])),0,1)))} -> 2 | U2: {=SUMPRODUCT((Nordics[Product Category]=$G2)*SUBTOTAL(109,OFFSET(INDEX(Nordics[26Q4],1),ROW(Nordics[26Q4])-MIN(ROW(Nordics[26Q4])),0,1)))} -> 50 | V2: {=SUMPRODUCT((Nordics[Product Category]=$G2)*SUBTOTAL(109,OFFSET(INDEX(Nordics[27M01],1),ROW(Nordics[27M01])-MIN(ROW(Nordics[27M01])),0,1)))} -> 0 | W2: {=SUMPRODUCT((Nordics[Product Category]=$G2)*SUBTOTAL(109,OFFSET(INDEX(Nordics[27M02],1),ROW(Nordics[27M02])-MIN(ROW(Nordics[27M02])),0,1)))} -> 0 | X2: {=SUMPRODUCT((Nordics[Product Category]=$G2)*SUBTOTAL(109,OFFSET(INDEX(Nordics[27M03],1),ROW(Nordics[27M03])-MIN(ROW(Nordics[27M03])),0,1)))} -> 0 | Y2: {=SUMPRODUCT((Nordics[Product Category]=$G2)*SUBTOTAL(109,OFFSET(INDEX(Nordics[27M04],1),ROW(Nordics[27M04])-MIN(ROW(Nordics[27M04])),0,1)))} -> 0 | Z2: {=SUMPRODUCT((Nordics[Product Category]=$G2)*SUBTOTAL(109,OFFSET(INDEX(Nordics[27M05],1),ROW(Nordics[27M05])-MIN(ROW(Nordics[27M05])),0,1)))} -> 0 | AA2: {=SUMPRODUCT((Nordics[Product Category]=$G2)*SUBTOTAL(109,OFFSET(INDEX(Nordics[27M06],1),ROW(Nordics[27M06])-MIN(ROW(Nordics[27M06])),0,1)))} -> 0 | AB2: {=SUMPRODUCT((Nordics[Product Category]=$G2)*SUBTOTAL(109,OFFSET(INDEX(Nordics[27Q1],1),ROW(Nordics[27Q1])-MIN(ROW(Nordics[27Q1])),0,1)))} -> 0 | AC2: {=SUMPRODUCT((Nordics[Product Category]=$G2)*SUBTOTAL(109,OFFSET(INDEX(Nordics[27Q2],1),ROW(Nordics[27Q2])-MIN(ROW(Nordics[27Q2])),0,1)))} -> 0
G3: HP | J3: {=SUMPRODUCT((Nordics[Product Category]=$G3)*SUBTOTAL(109,OFFSET(INDEX(Nordics[26M04],1),ROW(Nordics[26M04])-MIN(ROW(Nordics[26M04])),0,1)))} -> 0 | K3: {=SUMPRODUCT((Nordics[Product Category]=$G3)*SUBTOTAL(109,OFFSET(INDEX(Nordics[26M05],1),ROW(Nordics[26M05])-MIN(ROW(Nordics[26M05])),0,1)))} -> 0 | L3: {=SUMPRODUCT((Nordics[Product Category]=$G3)*SUBTOTAL(109,OFFSET(INDEX(Nordics[26M06],1),ROW(Nordics[26M06])-MIN(ROW(Nordics[26M06])),0,1)))} -> 0 | M3: {=SUMPRODUCT((Nordics[Product Category]=$G3)*SUBTOTAL(109,OFFSET(INDEX(Nordics[26M07],1),ROW(Nordics[26M07])-MIN(ROW(Nordics[26M07])),0,1)))} -> 2 | N3: {=SUMPRODUCT((Nordics[Product Category]=$G3)*SUBTOTAL(109,OFFSET(INDEX(Nordics[26M08],1),ROW(Nordics[26M08])-MIN(ROW(Nordics[26M08])),0,1)))} -> 0 | O3: {=SUMPRODUCT((Nordics[Product Category]=$G3)*SUBTOTAL(109,OFFSET(INDEX(Nordics[26M09],1),ROW(Nordics[26M09])-MIN(ROW(Nordics[26M09])),0,1)))} -> 0 | P3: {=SUMPRODUCT((Nordics[Product Category]=$G3)*SUBTOTAL(109,OFFSET(INDEX(Nordics[26M10],1),ROW(Nordics[26M10])-MIN(ROW(Nordics[26M10])),0,1)))} -> 0 | Q3: {=SUMPRODUCT((Nordics[Product Category]=$G3)*SUBTOTAL(109,OFFSET(INDEX(Nordics[26M11],1),ROW(Nordics[26M11])-MIN(ROW(Nordics[26M11])),0,1)))} -> 0 | R3: {=SUMPRODUCT((Nordics[Product Category]=$G3)*SUBTOTAL(109,OFFSET(INDEX(Nordics[26M12],1),ROW(Nordics[26M12])-MIN(ROW(Nordics[26M12])),0,1)))} -> 0 | S3: {=SUMPRODUCT((Nordics[Product Category]=$G3)*SUBTOTAL(109,OFFSET(INDEX(Nordics[26Q2],1),ROW(Nordics[26Q2])-MIN(ROW(Nordics[26Q2])),0,1)))} -> 0 | T3: {=SUMPRODUCT((Nordics[Product Category]=$G3)*SUBTOTAL(109,OFFSET(INDEX(Nordics[26Q3],1),ROW(Nordics[26Q3])-MIN(ROW(Nordics[26Q3])),0,1)))} -> 2 | U3: {=SUMPRODUCT((Nordics[Product Category]=$G3)*SUBTOTAL(109,OFFSET(INDEX(Nordics[26Q4],1),ROW(Nordics[26Q4])-MIN(ROW(Nordics[26Q4])),0,1)))} -> 0 | V3: {=SUMPRODUCT((Nordics[Product Category]=$G3)*SUBTOTAL(109,OFFSET(INDEX(Nordics[27M01],1),ROW(Nordics[27M01])-MIN(ROW(Nordics[27M01])),0,1)))} -> 0 | W3: {=SUMPRODUCT((Nordics[Product Category]=$G3)*SUBTOTAL(109,OFFSET(INDEX(Nordics[27M02],1),ROW(Nordics[27M02])-MIN(ROW(Nordics[27M02])),0,1)))} -> 0 | X3: {=SUMPRODUCT((Nordics[Product Category]=$G3)*SUBTOTAL(109,OFFSET(INDEX(Nordics[27M03],1),ROW(Nordics[27M03])-MIN(ROW(Nordics[27M03])),0,1)))} -> 0 | Y3: {=SUMPRODUCT((Nordics[Product Category]=$G3)*SUBTOTAL(109,OFFSET(INDEX(Nordics[27M04],1),ROW(Nordics[27M04])-MIN(ROW(Nordics[27M04])),0,1)))} -> 0 | Z3: {=SUMPRODUCT((Nordics[Product Category]=$G3)*SUBTOTAL(109,OFFSET(INDEX(Nordics[27M05],1),ROW(Nordics[27M05])-MIN(ROW(Nordics[27M05])),0,1)))} -> 0 | AA3: {=SUMPRODUCT((Nordics[Product Category]=$G3)*SUBTOTAL(109,OFFSET(INDEX(Nordics[27M06],1),ROW(Nordics[27M06])-MIN(ROW(Nordics[27M06])),0,1)))} -> 0 | AB3: {=SUMPRODUCT((Nordics[Product Category]=$G3)*SUBTOTAL(109,OFFSET(INDEX(Nordics[27Q1],1),ROW(Nordics[27Q1])-MIN(ROW(Nordics[27Q1])),0,1)))} -> 0 | AC3: {=SUMPRODUCT((Nordics[Product Category]=$G3)*SUBTOTAL(109,OFFSET(INDEX(Nordics[27Q2],1),ROW(Nordics[27Q2])-MIN(ROW(Nordics[27Q2])),0,1)))} -> 0
G4: PV | J4: {=SUMPRODUCT((Nordics[Product Category]=$G4)*SUBTOTAL(109,OFFSET(INDEX(Nordics[26M04],1),ROW(Nordics[26M04])-MIN(ROW(Nordics[26M04])),0,1)))} -> 6.4 | K4: {=SUMPRODUCT((Nordics[Product Category]=$G4)*SUBTOTAL(109,OFFSET(INDEX(Nordics[26M05],1),ROW(Nordics[26M05])-MIN(ROW(Nordics[26M05])),0,1)))} -> 6 | L4: {=SUMPRODUCT((Nordics[Product Category]=$G4)*SUBTOTAL(109,OFFSET(INDEX(Nordics[26M06],1),ROW(Nordics[26M06])-MIN(ROW(Nordics[26M06])),0,1)))} -> 8.4 | M4: {=SUMPRODUCT((Nordics[Product Category]=$G4)*SUBTOTAL(109,OFFSET(INDEX(Nordics[26M07],1),ROW(Nordics[26M07])-MIN(ROW(Nordics[26M07])),0,1)))} -> 6.3 | N4: {=SUMPRODUCT((Nordics[Product Category]=$G4)*SUBTOTAL(109,OFFSET(INDEX(Nordics[26M08],1),ROW(Nordics[26M08])-MIN(ROW(Nordics[26M08])),0,1)))} -> 7.5 | O4: {=SUMPRODUCT((Nordics[Product Category]=$G4)*SUBTOTAL(109,OFFSET(INDEX(Nordics[26M09],1),ROW(Nordics[26M09])-MIN(ROW(Nordics[26M09])),0,1)))} -> 58.3 | P4: {=SUMPRODUCT((Nordics[Product Category]=$G4)*SUBTOTAL(109,OFFSET(INDEX(Nordics[26M10],1),ROW(Nordics[26M10])-MIN(ROW(Nordics[26M10])),0,1)))} -> 20.6 | Q4: {=SUMPRODUCT((Nordics[Product Category]=$G4)*SUBTOTAL(109,OFFSET(INDEX(Nordics[26M11],1),ROW(Nordics[26M11])-MIN(ROW(Nordics[26M11])),0,1)))} -> 16 | R4: {=SUMPRODUCT((Nordics[Product Category]=$G4)*SUBTOTAL(109,OFFSET(INDEX(Nordics[26M12],1),ROW(Nordics[26M12])-MIN(ROW(Nordics[26M12])),0,1)))} -> 4 | S4: {=SUMPRODUCT((Nordics[Product Category]=$G4)*SUBTOTAL(109,OFFSET(INDEX(Nordics[26Q2],1),ROW(Nordics[26Q2])-MIN(ROW(Nordics[26Q2])),0,1)))} -> 16.95 | T4: {=SUMPRODUCT((Nordics[Product Category]=$G4)*SUBTOTAL(109,OFFSET(INDEX(Nordics[26Q3],1),ROW(Nordics[26Q3])-MIN(ROW(Nordics[26Q3])),0,1)))} -> 72.1 | U4: {=SUMPRODUCT((Nordics[Product Category]=$G4)*SUBTOTAL(109,OFFSET(INDEX(Nordics[26Q4],1),ROW(Nordics[26Q4])-MIN(ROW(Nordics[26Q4])),0,1)))} -> 40.6 | V4: {=SUMPRODUCT((Nordics[Product Category]=$G4)*SUBTOTAL(109,OFFSET(INDEX(Nordics[27M01],1),ROW(Nordics[27M01])-MIN(ROW(Nordics[27M01])),0,1)))} -> 0 | W4: {=SUMPRODUCT((Nordics[Product Category]=$G4)*SUBTOTAL(109,OFFSET(INDEX(Nordics[27M02],1),ROW(Nordics[27M02])-MIN(ROW(Nordics[27M02])),0,1)))} -> 0 | X4: {=SUMPRODUCT((Nordics[Product Category]=$G4)*SUBTOTAL(109,OFFSET(INDEX(Nordics[27M03],1),ROW(Nordics[27M03])-MIN(ROW(Nordics[27M03])),0,1)))} -> 0 | Y4: {=SUMPRODUCT((Nordics[Product Category]=$G4)*SUBTOTAL(109,OFFSET(INDEX(Nordics[27M04],1),ROW(Nordics[27M04])-MIN(ROW(Nordics[27M04])),0,1)))} -> 0 | Z4: {=SUMPRODUCT((Nordics[Product Category]=$G4)*SUBTOTAL(109,OFFSET(INDEX(Nordics[27M05],1),ROW(Nordics[27M05])-MIN(ROW(Nordics[27M05])),0,1)))} -> 0 | AA4: {=SUMPRODUCT((Nordics[Product Category]=$G4)*SUBTOTAL(109,OFFSET(INDEX(Nordics[27M06],1),ROW(Nordics[27M06])-MIN(ROW(Nordics[27M06])),0,1)))} -> 0 | AB4: {=SUMPRODUCT((Nordics[Product Category]=$G4)*SUBTOTAL(109,OFFSET(INDEX(Nordics[27Q1],1),ROW(Nordics[27Q1])-MIN(ROW(Nordics[27Q1])),0,1)))} -> 0 | AC4: {=SUMPRODUCT((Nordics[Product Category]=$G4)*SUBTOTAL(109,OFFSET(INDEX(Nordics[27Q2],1),ROW(Nordics[27Q2])-MIN(ROW(Nordics[27Q2])),0,1)))} -> 0
A5: Country | B5: Customer name | C5: RSM | D5: Brand | E5: Product Line | F5: Model name | G5: Stage | H5: Comments (Deal Breaker, spec/requirements, etc) | I5: Supply Chain | J5: 26M04 | K5: 26M05 | L5: 26M06 | M5: 26M07 | N5: 26M08 | O5: 26M09 | P5: 26M10 | Q5: 26M11 | R5: 26M12 | S5: 26Q2 | T5: 26Q3 | U5: 26Q4 | V5: 27M01 | W5: 27M02 | X5: 27M03 | Y5: 27M04 | Z5: 27M05 | AA5: 27M06 | AB5: 27Q1 | AC5: 27Q2 | AD5: Only 2026? | AE5: Product Category
A6: Nordic | B6: Nordic Sun Danmark A/S | C6: Filip Abrahamsson | D6: =VLOOKUP(Nordics[[#This Row],[Product Line]],Prod_T6[],5,0) -> TCL | E6: TCL_T_Class | F6: HSM-ND66-GR620 | G6: 4 - BAFO | H6: Asking for DDP price, Possible Caroline LI, Q2-Q3 Must win - Delayed Q4 due to permits----Long Cable---27Q1 | I6: Offshore/EU? | P6: 7 | Q6: 6 | T6: =SUM(Nordics[[#This Row],[26M07]:[26M09]]) -> 0 | U6: =SUM(Nordics[[#This Row],[26M10]:[26M12]]) -> 13 | AB6: =SUM(Nordics[[#This Row],[27M01]:[27M03]]) -> 0 | AC6: =SUM(Nordics[[#This Row],[27M04]:[27M06]]) -> 0 | AD6: =IF(SUM(Nordics[[#This Row],[26Q2]:[26Q4]])+SUM(Nordics[[#This Row],[27Q1]:[27Q2]])=0,"No FSCT",IF(AND(SUM(Nordics[[#This Row],[26Q2]:[26Q4]])>0,SUM(Nordics[[#This Row],[27Q1]:[27Q2]])=0),"YES","NO")) -> YES | AE6: =VLOOKUP(Nordics[[#This Row],[Product Line]],Prod_T6[],4,0) -> PV | AH6: {=Nordics[Stage]} -> 4 - BAFO
A7: Nordic | B7: Sunny Future AB | C7: Filip Abrahamsson | D7: =VLOOKUP(Nordics[[#This Row],[Product Line]],Prod_T6[],5,0) -> Sunpower | E7: SPR_M_Class | F7: SPR-BE54-DC480 | G7: 7 - Booked | H7: Upgrade to 485 or 480 | I7: EU | K7: 0.2 | S7: =SUM(Nordics[[#This Row],[26M04]:[26M06]]) -> 0.2 | T7: =SUM(Nordics[[#This Row],[26M07]:[26M09]]) -> 0 | U7: =SUM(Nordics[[#This Row],[26M10]:[26M12]]) -> 0 | AB7: =SUM(Nordics[[#This Row],[27M01]:[27M03]]) -> 0 | AC7: =SUM(Nordics[[#This Row],[27M04]:[27M06]]) -> 0 | AD7: =IF(SUM(Nordics[[#This Row],[26Q2]:[26Q4]])+SUM(Nordics[[#This Row],[27Q1]:[27Q2]])=0,"No FSCT",IF(AND(SUM(Nordics[[#This Row],[26Q2]:[26Q4]])>0,SUM(Nordics[[#This Row],[27Q1]:[27Q2]])=0),"YES","NO")) -> YES | AE7: =VLOOKUP(Nordics[[#This Row],[Product Line]],Prod_T6[],4,0) -> PV | AH7: 7 - Booked
A8: Nordic | B8: Solcellespesialisten AS | C8: Filip Abrahamsson | D8: =VLOOKUP(Nordics[[#This Row],[Product Line]],Prod_T6[],5,0) -> Sunpower | E8: SPR_P7 | F8: P7-BLK-P-510 | G8: 0 - Lost | H8: BANKRUPT Reactivation - Special project in portable mounting system EPD! required module can be changed, partner with Nordic Sun 20 MW. MAX 206 cm | I8: Bankrupt | S8: =SUM(Nordics[[#This Row],[26M04]:[26M06]]) -> 0 | T8: =SUM(Nordics[[#This Row],[26M07]:[26M09]]) -> 0 | U8: =SUM(Nordics[[#This Row],[26M10]:[26M12]]) -> 0 | AB8: =SUM(Nordics[[#This Row],[27M01]:[27M03]]) -> 0 | AC8: =SUM(Nordics[[#This Row],[27M04]:[27M06]]) -> 0 | AD8: =IF(SUM(Nordics[[#This Row],[26Q2]:[26Q4]])+SUM(Nordics[[#This Row],[27Q1]:[27Q2]])=0,"No FSCT",IF(AND(SUM(Nordics[[#This Row],[26Q2]:[26Q4]])>0,SUM(Nordics[[#This Row],[27Q1]:[27Q2]])=0),"YES","NO")) -> No FSCT | AE8: =VLOOKUP(Nordics[[#This Row],[Product Line]],Prod_T6[],4,0) -> PV | AH8: 0 - Lost
A9: Nordic | B9: Pareto Alternative investments | C9: Filip Abrahamsson | D9: =VLOOKUP(Nordics[[#This Row],[Product Line]],Prod_T6[],5,0) -> TCL | E9: TCL_T5_Pro | F9: HSM-NT66-GH 640/645 - T5_Pro_L_PP | G9: 1 - Lead qualification | H9: New C&I Norway, compete with AIKO | I9: Offshore | O9: 2 | S9: =SUM(Nordics[[#This Row],[26M04]:[26M06]]) -> 0 | T9: =SUM(Nordics[[#This Row],[26M07]:[26M09]]) -> 2 | U9: =SUM(Nordics[[#This Row],[26M10]:[26M12]]) -> 0 | AB9: =SUM(Nordics[[#This Row],[27M01]:[27M03]]) -> 0 | AC9: =SUM(Nordics[[#This Row],[27M04]:[27M06]]) -> 0 | AD9: =IF(SUM(Nordics[[#This Row],[26Q2]:[26Q4]])+SUM(Nordics[[#This Row],[27Q1]:[27Q2]])=0,"No FSCT",IF(AND(SUM(Nordics[[#This Row],[26Q2]:[26Q4]])>0,SUM(Nordics[[#This Row],[27Q1]:[27Q2]])=0),"YES","NO")) -> YES | AE9: =VLOOKUP(Nordics[[#This Row],[Product Line]],Prod_T6[],4,0) -> PV | AH9: 1 - Lead qualification
A10: Nordic | B10: Nordic Sun Danmark A/S | C10: Filip Abrahamsson | D10: =VLOOKUP(Nordics[[#This Row],[Product Line]],Prod_T6[],5,0) -> TCL | E10: TCL_T_Class | F10: HSM-ND66-GR620 | G10: 4 - BAFO | H10: C&I 10 Containers | I10: Offshore | J10: 2 | S10: =SUM(Nordics[[#This Row],[26M04]:[26M06]]) -> 2 | T10: =SUM(Nordics[[#This Row],[26M07]:[26M09]]) -> 0 | U10: =SUM(Nordics[[#This Row],[26M10]:[26M12]]) -> 0 | AB10: =SUM(Nordics[[#This Row],[27M01]:[27M03]]) -> 0 | AC10: =SUM(Nordics[[#This Row],[27M04]:[27M06]]) -> 0 | AD10: =IF(SUM(Nordics[[#This Row],[26Q2]:[26Q4]])+SUM(Nordics[[#This Row],[27Q1]:[27Q2]])=0,"No FSCT",IF(AND(SUM(Nordics[[#This Row],[26Q2]:[26Q4]])>0,SUM(Nordics[[#This Row],[27Q1]:[27Q2]])=0),"YES","NO")) -> YES | AE10: =VLOOKUP(Nordics[[#This Row],[Product Line]],Prod_T6[],4,0) -> PV | AH10: 4 - BAFO
A11: Nordic | B11: New Customer / Balance of others customers NO | D11: =VLOOKUP(Nordics[[#This Row],[Product Line]],Prod_T6[],5,0) -> TCL | E11: TCL_T_Class | F11: HSM-ND48-DR455 | G11: 6 - Won | I11: Offshore | J11: 2.4 | S11: =SUM(Nordics[[#This Row],[26M04]:[26M06]]) -> 2.4 | T11: =SUM(Nordics[[#This Row],[26M07]:[26M09]]) -> 0 | U11: =SUM(Nordics[[#This Row],[26M10]:[26M12]]) -> 0 | AB11: =SUM(Nordics[[#This Row],[27M01]:[27M03]]) -> 0 | AC11: =SUM(Nordics[[#This Row],[27M04]:[27M06]]) -> 0 | AD11: =IF(SUM(Nordics[[#This Row],[26Q2]:[26Q4]])+SUM(Nordics[[#This Row],[27Q1]:[27Q2]])=0,"No FSCT",IF(AND(SUM(Nordics[[#This Row],[26Q2]:[26Q4]])>0,SUM(Nordics[[#This Row],[27Q1]:[27Q2]])=0),"YES","NO")) -> YES | AE11: =VLOOKUP(Nordics[[#This Row],[Product Line]],Prod_T6[],4,0) -> PV | AH11: 6 - Won
A12: Nordic | B12: New Customer / Balance of others customers NO | D12: =VLOOKUP(Nordics[[#This Row],[Product Line]],Prod_T6[],5,0) -> TCL | E12: TCL_T_Class | F12: HSM-ND54-DR505 | G12: 6 - Won | I12: Offshore | J12: 2 | T12: =SUM(Nordics[[#This Row],[26M07]:[26M09]]) -> 0 | U12: =SUM(Nordics[[#This Row],[26M10]:[26M12]]) -> 0 | AB12: =SUM(Nordics[[#This Row],[27M01]:[27M03]]) -> 0 | AC12: =SUM(Nordics[[#This Row],[27M04]:[27M06]]) -> 0 | AD12: =IF(SUM(Nordics[[#This Row],[26Q2]:[26Q4]])+SUM(Nordics[[#This Row],[27Q1]:[27Q2]])=0,"No FSCT",IF(AND(SUM(Nordics[[#This Row],[26Q2]:[26Q4]])>0,SUM(Nordics[[#This Row],[27Q1]:[27Q2]])=0),"YES","NO")) -> No FSCT | AE12: =VLOOKUP(Nordics[[#This Row],[Product Line]],Prod_T6[],4,0) -> PV | AH12: 6 - Won
A13: Nordic | B13: Rexel Sweden | D13: =VLOOKUP(Nordics[[#This Row],[Product Line]],Prod_T6[],5,0) -> TCL | E13: TCL_T_Class | F13: HSM-ND48-DR455 | G13: 3 - Negotiation | H13: Placement for Q2 | I13: EU | K13: 2 | L13: 2 | N13: 1 | O13: 1 | S13: =SUM(Nordics[[#This Row],[26M04]:[26M06]]) -> 4 | T13: =SUM(Nordics[[#This Row],[26M07]:[26M09]]) -> 2 | U13: =SUM(Nordics[[#This Row],[26M10]:[26M12]]) -> 0 | AB13: =SUM(Nordics[[#This Row],[27M01]:[27M03]]) -> 0 | AC13: =SUM(Nordics[[#This Row],[27M04]:[27M06]]) -> 0 | AD13: =IF(SUM(Nordics[[#This Row],[26Q2]:[26Q4]])+SUM(Nordics[[#This Row],[27Q1]:[27Q2]])=0,"No FSCT",IF(AND(SUM(Nordics[[#This Row],[26Q2]:[26Q4]])>0,SUM(Nordics[[#This Row],[27Q1]:[27Q2]])=0),"YES","NO")) -> YES | AE13: =VLOOKUP(Nordics[[#This Row],[Product Line]],Prod_T6[],4,0) -> PV | AH13: 3 - Negotiation
A14: Nordic | B14: Rexel Sweden | D14: =VLOOKUP(Nordics[[#This Row],[Product Line]],Prod_T6[],5,0) -> TCL | E14: TCL_T_Class | F14: HSM-ND54-DR505 | G14: 7 - Booked | H14: Placement for Q2 | I14: EU | N14: 1 | S14: =SUM(Nordics[[#This Row],[26M04]:[26M06]]) -> 0 | T14: =SUM(Nordics[[#This Row],[26M07]:[26M09]]) -> 1 | U14: =SUM(Nordics[[#This Row],[26M10]:[26M12]]) -> 0 | AB14: =SUM(Nordics[[#This Row],[27M01]:[27M03]]) -> 0 | AC14: =SUM(Nordics[[#This Row],[27M04]:[27M06]]) -> 0 | AD14: =IF(SUM(Nordics[[#This Row],[26Q2]:[26Q4]])+SUM(Nordics[[#This Row],[27Q1]:[27Q2]])=0,"No FSCT",IF(AND(SUM(Nordics[[#This Row],[26Q2]:[26Q4]])>0,SUM(Nordics[[#This Row],[27Q1]:[27Q2]])=0),"YES","NO")) -> YES | AE14: =VLOOKUP(Nordics[[#This Row],[Product Line]],Prod_T6[],4,0) -> PV | AH14: 7 - Booked
A15: Nordic | B15: Rexel Sweden | D15: =VLOOKUP(Nordics[[#This Row],[Product Line]],Prod_T6[],5,0) -> TCL | E15: TCL_T_Class | F15: HSM-ND66-GR620 | G15: 3 - Negotiation | H15: Placement for Q2 | I15: EU | K15: 0.8 | M15: 0.8 | S15: =SUM(Nordics[[#This Row],[26M04]:[26M06]]) -> 0.8 | T15: =SUM(Nordics[[#This Row],[26M07]:[26M09]]) -> 0.8 | U15: =SUM(Nordics[[#This Row],[26M10]:[26M12]]) -> 0 | AB15: =SUM(Nordics[[#This Row],[27M01]:[27M03]]) -> 0 | AC15: =SUM(Nordics[[#This Row],[27M04]:[27M06]]) -> 0 | AD15: =IF(SUM(Nordics[[#This Row],[26Q2]:[26Q4]])+SUM(Nordics[[#This Row],[27Q1]:[27Q2]])=0,"No FSCT",IF(AND(SUM(Nordics[[#This Row],[26Q2]:[26Q4]])>0,SUM(Nordics[[#This Row],[27Q1]:[27Q2]])=0),"YES","NO")) -> YES | AE15: =VLOOKUP(Nordics[[#This Row],[Product Line]],Prod_T6[],4,0) -> PV | AH15: 3 - Negotiation
A16: Nordic | B16: Nordic Sun Danmark A/S | D16: =VLOOKUP(Nordics[[#This Row],[Product Line]],Prod_T6[],5,0) -> TCL | E16: TCL_T_Class | F16: HSM-ND48-DR455 | G16: 1 - Lead qualification | H16: Placement for Q2 | I16: Offshore | L16: 2 | M16: 2 | N16: 2 | O16: 2 | T16: =SUM(Nordics[[#This Row],[26M07]:[26M09]]) -> 6 | U16: =SUM(Nordics[[#This Row],[26M10]:[26M12]]) -> 0 | AB16: =SUM(Nordics[[#This Row],[27M01]:[27M03]]) -> 0 | AC16: =SUM(Nordics[[#This Row],[27M04]:[27M06]]) -> 0 | AD16: =IF(SUM(Nordics[[#This Row],[26Q2]:[26Q4]])+SUM(Nordics[[#This Row],[27Q1]:[27Q2]])=0,"No FSCT",IF(AND(SUM(Nordics[[#This Row],[26Q2]:[26Q4]])>0,SUM(Nordics[[#This Row],[27Q1]:[27Q2]])=0),"YES","NO")) -> YES | AE16: =VLOOKUP(Nordics[[#This Row],[Product Line]],Prod_T6[],4,0) -> PV | AH16: 1 - Lead qualification
A17: Nordic | B17: Nordic Sun Danmark A/S | D17: =VLOOKUP(Nordics[[#This Row],[Product Line]],Prod_T6[],5,0) -> Sunpower | E17: SPR_P7 | F17: P7-BLK-2mm-455 | G17: 1 - Lead qualification | H17: Price ? €0.18 not compatible, DSB project - whitelist against DMEGC - Offer €0.135 | I17: Offshore | L17: 1 | M17: 1 | N17: 1 | S17: =SUM(Nordics[[#This Row],[26M04]:[26M06]]) -> 1 | T17: =SUM(Nordics[[#This Row],[26M07]:[26M09]]) -> 2 | U17: =SUM(Nordics[[#This Row],[26M10]:[26M12]]) -> 0 | AB17: =SUM(Nordics[[#This Row],[27M01]:[27M03]]) -> 0 | AC17: =SUM(Nordics[[#This Row],[27M04]:[27M06]]) -> 0 | AD17: =IF(SUM(Nordics[[#This Row],[26Q2]:[26Q4]])+SUM(Nordics[[#This Row],[27Q1]:[27Q2]])=0,"No FSCT",IF(AND(SUM(Nordics[[#This Row],[26Q2]:[26Q4]])>0,SUM(Nordics[[#This Row],[27Q1]:[27Q2]])=0),"YES","NO")) -> YES | AE17: =VLOOKUP(Nordics[[#This Row],[Product Line]],Prod_T6[],4,0) -> PV | AH17: 1 - Lead qualification
A18: Nordic | B18: Rexel Sweden | D18: =VLOOKUP(Nordics[[#This Row],[Product Line]],Prod_T6[],5,0) -> TCL | E18: TCL_T_Class | F18: HSM-ND66-GR625 | G18: 1 - Lead qualification | H18: C&I Panatoni Warehouse PAN Nordic | I18: EU | M18: 0.5 | N18: 0.5 | O18: 0.5 | S18: =SUM(Nordics[[#This Row],[26M04]:[26M06]]) -> 0 | T18: =SUM(Nordics[[#This Row],[26M07]:[26M09]]) -> 1.5 | U18: =SUM(Nordics[[#This Row],[26M10]:[26M12]]) -> 0 | AB18: =SUM(Nordics[[#This Row],[27M01]:[27M03]]) -> 0 | AC18: =SUM(Nordics[[#This Row],[27M04]:[27M06]]) -> 0 | AD18: =IF(SUM(Nordics[[#This Row],[26Q2]:[26Q4]])+SUM(Nordics[[#This Row],[27Q1]:[27Q2]])=0,"No FSCT",IF(AND(SUM(Nordics[[#This Row],[26Q2]:[26Q4]])>0,SUM(Nordics[[#This Row],[27Q1]:[27Q2]])=0),"YES","NO")) -> YES | AE18: =VLOOKUP(Nordics[[#This Row],[Product Line]],Prod_T6[],4,0) -> PV | AH18: 1 - Lead qualification
A19: Nordic | B19: Rexel Sweden | D19: =VLOOKUP(Nordics[[#This Row],[Product Line]],Prod_T6[],5,0) -> Sunpower | E19: SPR_P7 | F19: P7-BLK-2mm-460 | G19: 1 - Lead qualification | H19: Placement for Q3 | I19: EU | M19: 1 | O19: 1 | S19: =SUM(Nordics[[#This Row],[26M04]:[26M06]]) -> 0 | T19: =SUM(Nordics[[#This Row],[26M07]:[26M09]]) -> 2 | U19: =SUM(Nordics[[#This Row],[26M10]:[26M12]]) -> 0 | AB19: =SUM(Nordics[[#This Row],[27M01]:[27M03]]) -> 0 | AC19: =SUM(Nordics[[#This Row],[27M04]:[27M06]]) -> 0 | AD19: =IF(SUM(Nordics[[#This Row],[26Q2]:[26Q4]])+SUM(Nordics[[#This Row],[27Q1]:[27Q2]])=0,"No FSCT",IF(AND(SUM(Nordics[[#This Row],[26Q2]:[26Q4]])>0,SUM(Nordics[[#This Row],[27Q1]:[27Q2]])=0),"YES","NO")) -> YES | AE19: =VLOOKUP(Nordics[[#This Row],[Product Line]],Prod_T6[],4,0) -> PV | AH19: 1 - Lead qualification
A20: Nordic | B20: Nordic Sun Danmark A/S | D20: =VLOOKUP(Nordics[[#This Row],[Product Line]],Prod_T6[],5,0) -> TCL | E20: TCL_T_Class | F20: HSM-ND66-GK730 | G20: 0 - Lost | H20: Project in Finland Delivery Q3-Q4 | I20: Offshore | O20: 34 | S20: =SUM(Nordics[[#This Row],[26M04]:[26M06]]) -> 0 | T20: =SUM(Nordics[[#This Row],[26M07]:[26M09]]) -> 34 | U20: =SUM(Nordics[[#This Row],[26M10]:[26M12]]) -> 0 | AB20: =SUM(Nordics[[#This Row],[27M01]:[27M03]]) -> 0 | AC20: =SUM(Nordics[[#This Row],[27M04]:[27M06]]) -> 0 | AD20: =IF(SUM(Nordics[[#This Row],[26Q2]:[26Q4]])+SUM(Nordics[[#This Row],[27Q1]:[27Q2]])=0,"No FSCT",IF(AND(SUM(Nordics[[#This Row],[26Q2]:[26Q4]])>0,SUM(Nordics[[#This Row],[27Q1]:[27Q2]])=0),"YES","NO")) -> YES | AE20: =VLOOKUP(Nordics[[#This Row],[Product Line]],Prod_T6[],4,0) -> PV | AH20: 0 - Lost
A21: Nordic | B21: Nordic Sun Danmark A/S | D21: =VLOOKUP(Nordics[[#This Row],[Product Line]],Prod_T6[],5,0) -> TCL | E21: TCL_S_Class | F21: TCL-MG720DT210-68NS | G21: 2 - Initial offer | H21: C&I GM Denmark | I21: Offshore | K21: 3 | L21: 3 | S21: =SUM(Nordics[[#This Row],[26M04]:[26M06]]) -> 6 | T21: =SUM(Nordics[[#This Row],[26M07]:[26M09]]) -> 0 | U21: =SUM(Nordics[[#This Row],[26M10]:[26M12]]) -> 0 | AB21: =SUM(Nordics[[#This Row],[27M01]:[27M03]]) -> 0 | AC21: =SUM(Nordics[[#This Row],[27M04]:[27M06]]) -> 0 | AD21: =IF(SUM(Nordics[[#This Row],[26Q2]:[26Q4]])+SUM(Nordics[[#This Row],[27Q1]:[27Q2]])=0,"No FSCT",IF(AND(SUM(Nordics[[#This Row],[26Q2]:[26Q4]])>0,SUM(Nordics[[#This Row],[27Q1]:[27Q2]])=0),"YES","NO")) -> YES | AE21: =VLOOKUP(Nordics[[#This Row],[Product Line]],Prod_T6[],4,0) -> PV | AH21: 2 - Initial offer
A22: Nordic | B22: Rexel Sweden | D22: =VLOOKUP(Nordics[[#This Row],[Product Line]],Prod_T6[],5,0) -> TCL | E22: TCL_T5_Pro | F22: HSM-NT48-HH 465/470 - T5_Pro_S_Black | G22: 1 - Lead qualification | H22: Offer €0.128 | I22: EU | N22: 1 | O22: 1 | P22: 1 | Q22: 1 | S22: =SUM(Nordics[[#This Row],[26M04]:[26M06]]) -> 0 | T22: =SUM(Nordics[[#This Row],[26M07]:[26M09]]) -> 2 | U22: =SUM(Nordics[[#This Row],[26M10]:[26M12]]) -> 2 | AB22: =SUM(Nordics[[#This Row],[27M01]:[27M03]]) -> 0 | AC22: =SUM(Nordics[[#This Row],[27M04]:[27M06]]) -> 0 | AD22: =IF(SUM(Nordics[[#This Row],[26Q2]:[26Q4]])+SUM(Nordics[[#This Row],[27Q1]:[27Q2]])=0,"No FSCT",IF(AND(SUM(Nordics[[#This Row],[26Q2]:[26Q4]])>0,SUM(Nordics[[#This Row],[27Q1]:[27Q2]])=0),"YES","NO")) -> YES | AE22: =VLOOKUP(Nordics[[#This Row],[Product Line]],Prod_T6[],4,0) -> PV | AH22: 1 - Lead qualification
A23: Nordic | B23: Nordic Sun Danmark A/S | D23: =VLOOKUP(Nordics[[#This Row],[Product Line]],Prod_T6[],5,0) -> TCL | E23: TCL_T5_Pro | F23: HSM-NT48-HH 465/470 - T5_Pro_S_Black | G23: 1 - Lead qualification | H23: Offer €0.128 | I23: offshore | N23: 1 | O23: 1 | P23: 1 | Q23: 1 | S23: =SUM(Nordics[[#This Row],[26M04]:[26M06]]) -> 0 | T23: =SUM(Nordics[[#This Row],[26M07]:[26M09]]) -> 2 | U23: =SUM(Nordics[[#This Row],[26M10]:[26M12]]) -> 2 | AB23: =SUM(Nordics[[#This Row],[27M01]:[27M03]]) -> 0 | AC23: =SUM(Nordics[[#This Row],[27M04]:[27M06]]) -> 0 | AD23: =IF(SUM(Nordics[[#This Row],[26Q2]:[26Q4]])+SUM(Nordics[[#This Row],[27Q1]:[27Q2]])=0,"No FSCT",IF(AND(SUM(Nordics[[#This Row],[26Q2]:[26Q4]])>0,SUM(Nordics[[#This Row],[27Q1]:[27Q2]])=0),"YES","NO")) -> YES | AE23: =VLOOKUP(Nordics[[#This Row],[Product Line]],Prod_T6[],4,0) -> PV | AH23: 1 - Lead qualification
A24: Nordic | B24: Rexel Sweden | D24: =VLOOKUP(Nordics[[#This Row],[Product Line]],Prod_T6[],5,0) -> TCL | E24: TCL_T_Class | F24: HSM-ND66-GR620 | G24: 6 - Won | I24: EU | L24: 0.4 | S24: =SUM(Nordics[[#This Row],[26M04]:[26M06]]) -> 0.4 | T24: =SUM(Nordics[[#This Row],[26M07]:[26M09]]) -> 0 | U24: =SUM(Nordics[[#This Row],[26M10]:[26M12]]) -> 0 | AB24: =SUM(Nordics[[#This Row],[27M01]:[27M03]]) -> 0 | AC24: =SUM(Nordics[[#This Row],[27M04]:[27M06]]) -> 0 | AD24: =IF(SUM(Nordics[[#This Row],[26Q2]:[26Q4]])+SUM(Nordics[[#This Row],[27Q1]:[27Q2]])=0,"No FSCT",IF(AND(SUM(Nordics[[#This Row],[26Q2]:[26Q4]])>0,SUM(Nordics[[#This Row],[27Q1]:[27Q2]])=0),"YES","NO")) -> YES | AE24: =VLOOKUP(Nordics[[#This Row],[Product Line]],Prod_T6[],4,0) -> PV | AH24: 6 - Won
A25: Nordic | B25: Nordic Sun Danmark A/S | D25: =VLOOKUP(Nordics[[#This Row],[Product Line]],Prod_T6[],5,0) -> TCL | E25: TCL_T_Class | F25: HSM-ND66-GR625 | G25: 3 - Negotiation | H25: Special SKU / short cable / HC connect | I25: Offshore | O25: 5 | S25: =SUM(Nordics[[#This Row],[26M04]:[26M06]]) -> 0 | T25: =SUM(Nordics[[#This Row],[26M07]:[26M09]]) -> 5 | U25: =SUM(Nordics[[#This Row],[26M10]:[26M12]]) -> 0 | AB25: =SUM(Nordics[[#This Row],[27M01]:[27M03]]) -> 0 | AC25: =SUM(Nordics[[#This Row],[27M04]:[27M06]]) -> 0 | AD25: =IF(SUM(Nordics[[#This Row],[26Q2]:[26Q4]])+SUM(Nordics[[#This Row],[27Q1]:[27Q2]])=0,"No FSCT",IF(AND(SUM(Nordics[[#This Row],[26Q2]:[26Q4]])>0,SUM(Nordics[[#This Row],[27Q1]:[27Q2]])=0),"YES","NO")) -> YES | AE25: =VLOOKUP(Nordics[[#This Row],[Product Line]],Prod_T6[],4,0) -> PV | AH25: 3 - Negotiation
A26: Nordic | B26: nordic Sun Danmark A/S | D26: =VLOOKUP(Nordics[[#This Row],[Product Line]],Prod_T6[],5,0) -> TCL | E26: TCL_T_Class | F26: HSM-ND66-GR630 | G26: 3 - Negotiation | H26: Special SKU / short cable / HC connect | I26: Offshore | O26: 10 | S26: =SUM(Nordics[[#This Row],[26M04]:[26M06]]) -> 0 | T26: =SUM(Nordics[[#This Row],[26M07]:[26M09]]) -> 10 | U26: =SUM(Nordics[[#This Row],[26M10]:[26M12]]) -> 0 | AB26: =SUM(Nordics[[#This Row],[27M01]:[27M03]]) -> 0 | AC26: =SUM(Nordics[[#This Row],[27M04]:[27M06]]) -> 0 | AD26: =IF(SUM(Nordics[[#This Row],[26Q2]:[26Q4]])+SUM(Nordics[[#This Row],[27Q1]:[27Q2]])=0,"No FSCT",IF(AND(SUM(Nordics[[#This Row],[26Q2]:[26Q4]])>0,SUM(Nordics[[#This Row],[27Q1]:[27Q2]])=0),"YES","NO")) -> YES | AE26: =VLOOKUP(Nordics[[#This Row],[Product Line]],Prod_T6[],4,0) -> PV | AH26: 3 - Negotiation
A27: Nordic | B27: Nordic Sun Danmark A/S | D27: =VLOOKUP(Nordics[[#This Row],[Product Line]],Prod_T6[],5,0) -> TCL | E27: TCL_C2_Series | F27: HSM-BE54-HD485/490 | G27: 4 - BAFO | H27: Offer BC delivered in Sept Q3 / Confirm WW 34 | I27: Offshore | P27: 2 | Q27: 2 | S27: =SUM(Nordics[[#This Row],[26M04]:[26M06]]) -> 0 | T27: =SUM(Nordics[[#This Row],[26M07]:[26M09]]) -> 0 | U27: =SUM(Nordics[[#This Row],[26M10]:[26M12]]) -> 4 | AB27: =SUM(Nordics[[#This Row],[27M01]:[27M03]]) -> 0 | AC27: =SUM(Nordics[[#This Row],[27M04]:[27M06]]) -> 0 | AD27: =IF(SUM(Nordics[[#This Row],[26Q2]:[26Q4]])+SUM(Nordics[[#This Row],[27Q1]:[27Q2]])=0,"No FSCT",IF(AND(SUM(Nordics[[#This Row],[26Q2]:[26Q4]])>0,SUM(Nordics[[#This Row],[27Q1]:[27Q2]])=0),"YES","NO")) -> YES | AE27: =VLOOKUP(Nordics[[#This Row],[Product Line]],Prod_T6[],4,0) -> PV | AH27: 4 - BAFO
A28: Nordic | B28: Rexel Sweden | D28: =VLOOKUP(Nordics[[#This Row],[Product Line]],Prod_T6[],5,0) -> TCL | E28: TCL_C2_Series | F28: HSM-BE54-HD485/490 | G28: 6 - Won | H28: Offer BC delivered in Sept Q3 | I28: Offshore | P28: 1.6 | S28: =SUM(Nordics[[#This Row],[26M04]:[26M06]]) -> 0 | T28: =SUM(Nordics[[#This Row],[26M07]:[26M09]]) -> 0 | U28: =SUM(Nordics[[#This Row],[26M10]:[26M12]]) -> 1.6 | AB28: =SUM(Nordics[[#This Row],[27M01]:[27M03]]) -> 0 | AC28: =SUM(Nordics[[#This Row],[27M04]:[27M06]]) -> 0 | AD28: =IF(SUM(Nordics[[#This Row],[26Q2]:[26Q4]])+SUM(Nordics[[#This Row],[27Q1]:[27Q2]])=0,"No FSCT",IF(AND(SUM(Nordics[[#This Row],[26Q2]:[26Q4]])>0,SUM(Nordics[[#This Row],[27Q1]:[27Q2]])=0),"YES","NO")) -> YES | AE28: =VLOOKUP(Nordics[[#This Row],[Product Line]],Prod_T6[],4,0) -> PV | AH28: 6 - Won
A29: Nordic | B29: Rexel Sweden | D29: =VLOOKUP(Nordics[[#This Row],[Product Line]],Prod_T6[],5,0) -> Sunpower | E29: SPR_P7 | F29: P7-BLK-2mm-460 | G29: 6 - Won | H29: Q3 Order | I29: EU | M29: 0.4 | S29: =SUM(Nordics[[#This Row],[26M04]:[26M06]]) -> 0 | T29: =SUM(Nordics[[#This Row],[26M07]:[26M09]]) -> 0.4 | U29: =SUM(Nordics[[#This Row],[26M10]:[26M12]]) -> 0 | AB29: =SUM(Nordics[[#This Row],[27M01]:[27M03]]) -> 0 | AC29: =SUM(Nordics[[#This Row],[27M04]:[27M06]]) -> 0 | AD29: =IF(SUM(Nordics[[#This Row],[26Q2]:[26Q4]])+SUM(Nordics[[#This Row],[27Q1]:[27Q2]])=0,"No FSCT",IF(AND(SUM(Nordics[[#This Row],[26Q2]:[26Q4]])>0,SUM(Nordics[[#This Row],[27Q1]:[27Q2]])=0),"YES","NO")) -> YES | AE29: =VLOOKUP(Nordics[[#This Row],[Product Line]],Prod_T6[],4,0) -> PV | AH29: 6 - Won
A30: Nordic | B30: Rexel Sweden | D30: =VLOOKUP(Nordics[[#This Row],[Product Line]],Prod_T6[],5,0) -> Sunpower | E30: SPR_P7 | F30: P7-BLK-P-515 | G30: 6 - Won | H30: Q3 Order | I30: EU | M30: 0.4 | S30: =SUM(Nordics[[#This Row],[26M04]:[26M06]]) -> 0 | T30: =SUM(Nordics[[#This Row],[26M07]:[26M09]]) -> 0.4 | U30: =SUM(Nordics[[#This Row],[26M10]:[26M12]]) -> 0 | AB30: =SUM(Nordics[[#This Row],[27M01]:[27M03]]) -> 0 | AC30: =SUM(Nordics[[#This Row],[27M04]:[27M06]]) -> 0 | AD30: =IF(SUM(Nordics[[#This Row],[26Q2]:[26Q4]])+SUM(Nordics[[#This Row],[27Q1]:[27Q2]])=0,"No FSCT",IF(AND(SUM(Nordics[[#This Row],[26Q2]:[26Q4]])>0,SUM(Nordics[[#This Row],[27Q1]:[27Q2]])=0),"YES","NO")) -> YES | AE30: =VLOOKUP(Nordics[[#This Row],[Product Line]],Prod_T6[],4,0) -> PV | AH30: 6 - Won
A31: Nordic | B31: Site Services A/S | D31: =VLOOKUP(Nordics[[#This Row],[Product Line]],Prod_T6[],5,0) -> Sunpower | E31: SPR_MAX_P6 | F31: SPR_MAX_P6 | G31: 6 - Won | H31: New Customer Depletion Maxeon 390-400 COM | I31: EU | M31: 0.2 | T31: =SUM(Nordics[[#This Row],[26M07]:[26M09]]) -> 0.2 | U31: =SUM(Nordics[[#This Row],[26M10]:[26M12]]) -> 0 | AB31: =SUM(Nordics[[#This Row],[27M01]:[27M03]]) -> 0 | AC31: =SUM(Nordics[[#This Row],[27M04]:[27M06]]) -> 0 | AD31: =IF(SUM(Nordics[[#This Row],[26Q2]:[26Q4]])+SUM(Nordics[[#This Row],[27Q1]:[27Q2]])=0,"No FSCT",IF(AND(SUM(Nordics[[#This Row],[26Q2]:[26Q4]])>0,SUM(Nordics[[#This Row],[27Q1]:[27Q2]])=0),"YES","NO")) -> YES | AE31: =VLOOKUP(Nordics[[#This Row],[Product Line]],Prod_T6[],4,0) -> PV | AH31: 6 - Won
