Workbook
Name date_end_horizon: DATE(2026,11,15)
Name fx_qty: SUMIFS('H2-2025 PV DATA'!A:A,'H2-2025 PV DATA'!$C:$C,'H2-2025 PV DATA'!$A1)
Name fx_qty: SUMIFS('PV SUPPLY DATA'!A:A,'PV SUPPLY DATA'!$C:$C,'PV SUPPLY DATA'!$A1)

Sheet H1-2026 PV DATA
A1: TCL REFERENCE | B1: Factory Location | C1: FX_QTY criteria | D1: CHANNEL | E1: New Ark PO Type | F1: New Ark WH | G1: TCL-HK PO INCOTERM Requested | H1: B/L Consignee | I1: Priority Level | J1: ALLOCATION Planning | K1: SPWR SO Number | L1: SPWR SO Line | M1: G2G / Planning | N1: Factory Available Date | O1: PRODUCT TYPE | P1: New Ark SKU | Q1: Model | R1: Connector | S1: Cable Length | T1: WATT | U1: QUANTITY | V1: MW | W1: PALLETS | X1: CONTAINERS | Y1: STATUS | Z1: COMPLETED or IN-TRANSIT | AA1: ETR | AB1: Pick-Up Date | AC1: Pick-Up Week | AD1: SPTN-PVHK New Ark PO# | AE1: SPTN-HKPV ORacle PO# | AF1: PORT OF LOADING | AG1: POL | AH1: PORT DESTINATION | AI1: ETD On S/O | AJ1: ETD Update | AK1: ATD PORT | AL1: ETA On S/O | AM1: ETA Update | AN1: ATA PORT | AO1: Incoterm | AP1: REFERENCE V.V | AQ1: Carrier | AR1: TCL Invoice# or PO# | AS1: MBL/HBL# | AT1: BOOKING# | AU1: Leg2 leadtime On S/O | AV1: Telex released | AW1: ODP ETA Port | AX1: New Ark PO status | AY1: NewArk ETA PO | AZ1: Customs/Leg3 Assumption | BA1: ETA for New Ark update | BB1: ETA Year | BC1: ETA Month | BD1: ETA Week | BE1: Qty/Pallet | BF1: Qty/CT | BG1: Back Glass | BH1: Shipping Line
A2: OCT009.05 | B2: Tianjin | C2: OCT009 | D2: CORE DG | E2: Internal | F2: Arrival Plan-SPTN | G2: DAP | H2: SunPower Energy Solutions France SAS | I2: n/a | J2: Local WH | M2: n/a | N2: n/a | O2: Half Cut | P2: GF0700000071 | Q2: HSM-ND54-DR500 | R2: EVO2A | S2: ±1200mm | T2: 500 | U2: 2592 | V2: 1.296 | W2: 72 | X2: 3 | Y2: COMPLETED | Z2: COMPLETED | AB2: 46003 | AC2: 50 | AD2: POPV260114015 | AE2: 371009290 | AF2: TIANJIN | AG2: Tianjin | AH2: FOS SUR MER | AI2: 46009 | AJ2: 46009 | AK2: 46012 | AL2: 46076 | AM2: 46098 | AN2: 46099 | AO2: DAP | AP2: COSCO SHIPPING CAPRICORN/039W | AQ2: COSCO | AR2: TPVB20251205009 | AS2: COSU6437850520 | AT2: COSU6437850520 | AU2: 87 | AV2: SWB | AW2: 46099 | AX2: In Stock-Approved | AY2: 46112 | AZ2: 8 | BA2: 46107 | BB2: 2026 | BC2: 3 | BD2: 13 | BE2: 36 | BF2: 864 | BG2: Black glazing | BH2: AEM
A3: NOV008.04 | B3: Tianjin | C3: NOV008 | D3: CORE DG | E3: Internal | F3: Arrival Plan-SPTN | G3: DAP | H3: SunPower Energy Solutions France SAS | I3: n/a | J3: SPTN / NED | K3: 46010796 / FR0125122900758 | M3: n/a | N3: n/a | O3: Half Cut | P3: GF0700000080 | Q3: HSM-ND48-DR450_CFP | R3: EVO2A | S3: ±1200mm | T3: 450 | U3: 936 | V3: 0.421 | W3: 26 | X3: 1 | Y3: COMPLETED | Z3: COMPLETED | AB3: 46003 | AC3: 50 | AD3: POPV260114013 | AE3: 371009297 | AF3: TIANJIN | AG3: Tianjin | AH3: FOS SUR MER | AI3: 46009 | AJ3: 46009 | AK3: 46012 | AL3: 46076 | AM3: 46098 | AN3: 46099 | AO3: DAP | AP3: COSCO SHIPPING CAPRICORN/039W | AQ3: COSCO | AR3: TPVB20251205009 | AS3: COSU6437850520 | AT3: COSU6437850520 | AU3: 87 | AV3: SWB | AW3: 46099 | AX3: In Stock-Approved | AY3: 46112 | AZ3: 8 | BA3: 46107 | BB3: 2026 | BC3: 3 | BD3: 13 | BE3: 36 | BF3: 936 | BG3: Transparent | BH3: AEM
A4: NOV008.07 | B4: Tianjin | C4: NOV008 | D4: CORE DG | E4: Internal | F4: Arrival Plan-SPTN | G4: DAP | H4: SunPower Energy Solutions France SAS | I4: n/a | J4: Local WH | M4: n/a | N4: n/a | O4: Half Cut | P4: GF0700000080 | Q4: HSM-ND48-DR450_CFP | R4: EVO2A | S4: ±1200mm | T4: 450 | U4: 2808 | V4: 1.264 | W4: 78 | X4: 3 | Y4: COMPLETED | Z4: COMPLETED | AB4: 46003 | AC4: 50 | AD4: POPV260114014 | AE4: 371009298 | AF4: TIANJIN | AG4: Tianjin | AH4: FOS SUR MER | AI4: 46009 | AJ4: 46009 | AK4: 46012 | AL4: 46076 | AM4: 46098 | AN4: 46099 | AO4: DAP | AP4: COSCO SHIPPING CAPRICORN/039W | AQ4: COSCO | AR4: TPVB20251205009 | AS4: COSU6437850520 | AT4: COSU6437850520 | AU4: 87 | AV4: SWB | AW4: 46099 | AX4: In Stock-Approved | AY4: 46112 | AZ4: 8 | BA4: 46107 | BB4: 2026 | BC4: 3 | BD4: 13 | BE4: 36 | BF4: 936 | BG4: Transparent | BH4: AEM
A5: OCT012.02 | B5: Tianjin | C5: OCT012 | D5: CORE DG | E5: Internal | F5: Arrival Plan-SPNL | G5: DAP | H5: SunPower Energy Solutions France SAS | I5: n/a | J5: Distributors Italy - W72 | M5: n/a | N5: n/a | O5: Half Cut | P5: GF0101010095 | Q5: HSM-ND66-GR620 | R5: EVO2A | S5: ±1200mm | T5: 620 | U5: 4320 | V5: 2.678 | W5: 120 | X5: 6 | Y5: COMPLETED | Z5: COMPLETED | AB5: 46000 | AC5: 50 | AD5: POPV260224025 | AE5: 371009291 | AF5: TIANJIN | AG5: Tianjin | AH5: ROTTERDAM | AI5: 46009 | AJ5: 46009 | AK5: 46012 | AL5: 46061 | AM5: 46111 | AN5: 46111 | AO5: DAP | AP5: COSCO SHIPPING CAPRICORN/039W | AQ5: COSCO | AR5: TPVB20251205010 | AS5: COSU6437850970 | AT5: COSU6437850970 | AU5: 99 | AV5: SWB | AW5: 46111 | AX5: In Stock-Approved | AY5: 46125 | AZ5: 7 | BA5: 46118 | BB5: 2026 | BC5: 4 | BD5: 15 | BE5: 36 | BF5: 720 | BG5: White glazing | BH5: AEU
A6: DEC003.09 | B6: Yixing | C6: DEC003 | D6: UPP | E6: Internal | F6: Arrival Plan-SPES | G6: DAP | H6: Sunpower Energy Systems Spain, S.L.U. | I6: n/a | J6: SPES / Total Portugal | K6: PT0125122900789 | M6: n/a | N6: n/a | O6: Half Cut | P6: GF0700001575 | Q6: HSM-ND78-GF640 | R6: EVO2A | S6: ±1400mm | T6: 640 | U6: 2304 | V6: 1.475 | W6: 64 | X6: 4 | Y6: COMPLETED | Z6: COMPLETED | AB6: 46015 | AC6: 52 | AD6: POPV260115029 | AF6: SHANGHAI | AG6: Shanghai | AH6: VALENCIA | AI6: 46020 | AJ6: 46030 | AK6: 46030 | AL6: 46072 | AM6: 46092 | AN6: 46094 | AO6: DAP | AP6: COSCO SHIPPING PISCES 031W | AQ6: COSCO | AR6: TPVB20251212006 | AS6: COSU6438488340 | AT6: COSU6438488340 | AU6: 64 | AW6: 46094 | AX6: In Stock-Approved | AY6: 46104 | AZ6: 9 | BA6: 46103 | BB6: 2026 | BC6: 3 | BD6: 12 | BE6: 36 | BF6: 576 | BG6: Redirection Film | BH6: AEM
A7: DEC012.04 | B7: Yixing | C7: DEC012 | D7: CORE DG | E7: Internal | F7: Arrival Plan-SPTN | G7: DAP | H7: SunPower Energy Solutions France SAS | I7: n/a | J7: Local WH - SPTN W74 (Italy) | M7: n/a | N7: n/a | O7: Shingle | P7: GF0700000811 | Q7: TCL-MG720DT210-68NS | R7: EVO2A | S7: ±1400mm | T7: 720 | U7: 1782 | V7: 1.283 | W7: 54 | X7: 3 | Y7: COMPLETED | Z7: COMPLETED | AB7: 46012 | AC7: 51 | AD7: POPV260224037 | AF7: SHANGHAI | AG7: Shanghai | AH7: FOS SUR MER | AI7: 46020 | AJ7: 46030 | AK7: 46030 | AL7: 46064 | AM7: 46098 | AN7: 46099 | AO7: DAP | AP7: COSCO SHIPPING PISCES 031W | AQ7: COSCO | AR7: TPVB20251212007 | AS7: COSU6438902550 | AT7: COSU6438902550 | AU7: 69 | AW7: 46099 | AX7: In Stock-Approved | AY7: 46112 | AZ7: 8 | BA7: 46107 | BB7: 2026 | BC7: 3 | BD7: 13 | BE7: 33 | BF7: 594 | BG7: White glazing | BH7: AEM
A8: DEC012.01 | B8: Yixing | C8: DEC012 | D8: CORE DG | E8: Internal | F8: Arrival Plan-SPNL | G8: DAP | H8: SunPower Energy Solutions France SAS | I8: n/a | J8: Distributors Italy - W72 | M8: n/a | N8: n/a | O8: Shingle | P8: GF0700000811 | Q8: TCL-MG720DT210-68NS | R8: EVO2A | S8: ±1400mm | T8: 720 | U8: 1782 | V8: 1.283 | W8: 54 | X8: 3 | Y8: COMPLETED | Z8: COMPLETED | AB8: 46008 | AC8: 51 | AD8: POPV260217050 | AF8: SHANGHAI | AG8: Shanghai | AH8: ROTTERDAM | AI8: 46014 | AJ8: 46018 | AK8: 46017 | AL8: 46073 | AM8: 46090 | AN8: 46090 | AO8: DAP | AP8: COSCO SHIPPING KILIMANJARO 043W | AQ8: COSCO | AR8: TPVB20251212008 | AS8: COSU6438512470 | AT8: COSU6438512470 | AU8: 73 | AW8: 46090 | AX8: In Stock-Approved | AY8: 46104 | AZ8: 7 | BA8: 46097 | BB8: 2026 | BC8: 3 | BD8: 12 | BE8: 33 | BF8: 594 | BG8: White glazing | BH8: AEU
A9: NOV008.01 | B9: Tianjin | C9: NOV008 | D9: CORE DG | E9: Offshore | F9: SPTN Offstore in Transit WH | G9: CIP | H9: Ecostal France | I9: n/a | J9: Ecostal France | K9: 46010731 | M9: n/a | N9: n/a | O9: Half Cut | P9: GF0700000080 | Q9: HSM-ND48-DR450_CFP | R9: EVO2A | S9: ±1200mm | T9: 450 | U9: 936 | V9: 0.421 | W9: 26 | X9: 1 | Y9: COMPLETED | Z9: COMPLETED | AB9: 46009 | AC9: 51 | AD9: POPV260104138 | AE9: 371009343 | AF9: TIANJIN | AG9: Tianjin | AH9: FOS SUR MER | AI9: 46017 | AJ9: 46018 | AK9: 46018 | AL9: 46077 | AM9: 46090 | AN9: 46090 | AO9: CIP | AP9: COSCO SHIPPING VIRGO 034W | AQ9: COSCO | AR9: 46010731&817 | AS9: COSU9505137680 | AT9: COSU9505137680 | AU9: 72 | AV9: SWB | AW9: 46090 | AX9: In Stock-Approved | AY9: 46026 | AZ9: - | BA9: 46090 | BB9: 2026 | BC9: 3 | BD9: 11 | BE9: 36 | BF9: 936 | BG9: Transparent | BH9: AEM
A10: NOV008.02 | B10: Tianjin | C10: NOV008 | D10: CORE DG | E10: Offshore | F10: SPTN Offstore in Transit WH | G10: CIP | H10: Ecostal France | I10: n/a | J10: Ecostal France | K10: 46010817 | M10: n/a | N10: n/a | O10: Half Cut | P10: GF0700000080 | Q10: HSM-ND48-DR450_CFP | R10: EVO2A | S10: ±1200mm | T10: 450 | U10: 936 | V10: 0.421 | W10: 26 | X10: 1 | Y10: COMPLETED | Z10: COMPLETED | AB10: 46009 | AC10: 51 | AD10: POPV260104116 | AE10: 371009344 | AF10: TIANJIN | AG10: Tianjin | AH10: FOS SUR MER | AI10: 46017 | AJ10: 46018 | AK10: 46018 | AL10: 46077 | AM10: 46090 | AN10: 46090 | AO10: CIP | AP10: COSCO SHIPPING VIRGO 034W | AQ10: COSCO | AR10: 46010731&817 | AS10: COSU9505137680 | AT10: COSU9505137680 | AU10: 72 | AV10: SWB | AW10: 46090 | AX10: In Stock-Approved | AY10: 46026 | AZ10: - | BA10: 46090 | BB10: 2026 | BC10: 3 | BD10: 11 | BE10: 36 | BF10: 936 | BG10: Transparent | BH10: AEM
A11: OCT009.06 | B11: Tianjin | C11: OCT009 | D11: CORE DG | E11: Offshore | F11: SPTN Offstore in Transit WH | G11: FOB | H11: UAB Elmitra | I11: n/a | J11: UAB Elmitra | K11: 46011026 | M11: n/a | N11: n/a | O11: Half Cut | P11: GF0700000071 | Q11: HSM-ND54-DR500 | R11: EVO2A | S11: ±1200mm | T11: 500 | U11: 2592 | V11: 1.296 | W11: 72 | X11: 3 | Y11: COMPLETED | Z11: COMPLETED | AB11: 46011 | AC11: 51 | AD11: POPV260104081 | AE11: 371009338 | AF11: TIANJIN | AG11: Tianjin | AH11: KLAIPEDA | AI11: 46020 | AJ11: 46022 | AK11: 46020 | AL11: 46088 | AM11: 46106 | AN11: 46106 | AO11: FOB | AP11: MSC CARMELA/GA552W | AQ11: OTHER | AR11: 46011026 | AS11: 1071458212 | AT11: 177KKNPPXTNN5247 | AU11: 86 | AW11: 46106 | AX11: In Stock-Approved | AY11: 46026 | AZ11: - | BA11: 46106 | BB11: 2026 | BC11: 3 | BD11: 13 | BE11: 36 | BF11: 864 | BG11: Black glazing | BH11: AEU
A12: OCT012.03 | B12: Tianjin | C12: OCT012 | D12: CORE DG | E12: Internal | F12: Arrival Plan-SPNL | G12: DAP | H12: SunPower Energy Solutions France SAS | I12: n/a | J12: Distributors Italy - W72 | M12: n/a | N12: n/a | O12: Half Cut | P12: GF0101010095 | Q12: HSM-ND66-GR620 | R12: EVO2A | S12: ±1200mm | T12: 620 | U12: 4320 | V12: 2.678 | W12: 120 | X12: 6 | Y12: COMPLETED | Z12: COMPLETED | AB12: 46009 | AC12: 51 | AD12: POPV260224026 | AF12: TIANJIN | AG12: Tianjin | AH12: ROTTERDAM | AI12: 46017 | AJ12: 46018 | AK12: 46018 | AL12: 46078 | AM12: 46111 | AN12: 46111 | AO12: DAP | AP12: COSCO SHIPPING VIRGO 034W | AQ12: COSCO | AR12: TPVB20251212011 | AS12: COSU6438568500 | AT12: COSU6438568500 | AU12: 93 | AV12: SWB | AW12: 46111 | AX12: In Stock-Approved | AY12: 46125 | AZ12: 7 | BA12: 46118 | BB12: 2026 | BC12: 4 | BD12: 15 | BE12: 36 | BF12: 720 | BG12: White glazing | BH12: AEU
A13: DEC009.02 | B13: Yixing | C13: DEC009 | D13: CORE DG | E13: Internal | F13: Arrival Plan-SPNL | G13: DAP | H13: SunPower Energy Solutions France SAS | I13: n/a | J13: Local WH - W72 (Italy) | M13: n/a | N13: n/a | O13: P7 COM S BF IT | P13: GF0700000769 | Q13: PVM, SPR-P7-555-COM-S, I BF-G M4.3D EVO2Z6NL 1.5KV IT | R13: EVO2A | S13: ±1400mm | T13: 555 | U13: 1320 | V13: 0.733 | W13: 40 | X13: 2 | Y13: COMPLETED | Z13: COMPLETED | AB13: 46013 | AC13: 52 | AD13: POPV260217038 | AF13: SHANGHAI | AG13: Shanghai | AH13: ROTTERDAM | AI13: 46021 | AJ13: 46031 | AK13: 46030 | AL13: 46075 | AM13: 46111 | AN13: 46111 | AO13: DAP | AP13: CSCL URANUS 107W | AQ13: COSCO | AR13: TPVB20251219006 | AS13: COSU6439187330 | AT13: COSU6439187330 | AU13: 81 | AW13: 46111 | AX13: In Stock-Approved | AY13: 46125 | AZ13: 7 | BA13: 46118 | BB13: 2026 | BC13: 4 | BD13: 15 | BE13: 33 | BF13: 660 | BG13: White glazing | BH13: AEU
A14: DEC003.04 | B14: Yixing | C14: DEC003 | D14: UPP | E14: Internal | F14: Arrival Plan-SPES | G14: DAP | H14: Sunpower Energy Systems Spain, S.L.U. | I14: n/a | J14: SPES / Total Portugal | K14: PT0125122900789 | M14: n/a | N14: n/a | O14: Half Cut | P14: GF0700001575 | Q14: HSM-ND78-GF640 | R14: EVO2A | S14: ±1400mm | T14: 640 | U14: 1152 | V14: 0.737 | W14: 32 | X14: 2 | Y14: COMPLETED | Z14: COMPLETED | AB14: 46018 | AC14: 52 | AD14: POPV260115034 | AF14: SHANGHAI | AG14: Shanghai | AH14: VALENCIA | AI14: 46021 | AJ14: 46031 | AK14: 46030 | AL14: 46065 | AM14: 46088 | AN14: 46089 | AO14: DAP | AP14: CSCL URANUS 107W | AQ14: COSCO | AR14: TPVB20251219004 | AS14: COSU6439185140 | AT14: COSU6439185140 | AU14: 59 | AW14: 46089 | AX14: In Stock-Approved | AY14: 46100 | AZ14: 9 | BA14: 46098 | BB14: 2026 | BC14: 3 | BD14: 12 | BE14: 36 | BF14: 576 | BG14: Redirection Film | BH14: AEM
A15: DEC012.05 | B15: Yixing | C15: DEC012 | D15: CORE DG | E15: Internal | F15: Arrival Plan-SPTN | G15: DAP | H15: SunPower Energy Solutions France SAS | I15: n/a | J15: Local WH - SPTN W74 (Italy) | M15: n/a | N15: n/a | O15: Shingle | P15: GF0700000811 | Q15: TCL-MG720DT210-68NS | R15: EVO2A | S15: ±1400mm | T15: 720 | U15: 4752 | V15: 3.421 | W15: 144 | X15: 8 | Y15: COMPLETED | Z15: COMPLETED | AB15: 46021 | AC15: 1 | AD15: POPV260224033 | AF15: SHANGHAI | AG15: Shanghai | AH15: FOS SUR MER | AI15: 46027 | AJ15: 46029 | AK15: 46030 | AL15: 46073 | AM15: 46098 | AN15: 46099 | AO15: DAP | AP15: EVER GOLDEN 0733-031W | AQ15: COSCO | AR15: TPVB20251219005 | AS15: COSU6440016030 | AT15: COSU6440016030 | AU15: 69 | AW15: 46099 | AX15: In Stock-Approved | AY15: 46112 | AZ15: 8 | BA15: 46107 | BB15: 2026 | BC15: 3 | BD15: 13 | BE15: 33 | BF15: 594 | BG15: White glazing | BH15: AEM
A16: NOV005.02 | B16: Yixing | C16: NOV005 | D16: CORE DG | E16: Internal | F16: Arrival Plan-SPTN | G16: DAP | H16: SunPower Energy Solutions France SAS | I16: n/a | J16: Distributors Italy - SPTN W74 | M16: n/a | N16: n/a | O16: Shingle | P16: GF0700001578 | Q16: TCL-MR465DT182-58NS | R16: EVO2A | S16: ±1200mm | T16: 465 | U16: 4320 | V16: 2.009 | W16: 120 | X16: 5 | Y16: COMPLETED | Z16: COMPLETED | AB16: 46021 | AC16: 1 | AD16: POPV260224034 | AF16: SHANGHAI | AG16: Shanghai | AH16: FOS SUR MER | AI16: 46027 | AJ16: 46029 | AK16: 46030 | AL16: 46073 | AM16: 46098 | AN16: 46099 | AO16: DAP | AP16: EVER GOLDEN 0733-031W | AQ16: COSCO | AR16: TPVB20251219005 | AS16: COSU6440016030 | AT16: COSU6440016030 | AU16: 69 | AW16: 46099 | AX16: In Stock-Approved | AY16: 46112 | AZ16: 8 | BA16: 46107 | BB16: 2026 | BC16: 3 | BD16: 13 | BE16: 36 | BF16: 864 | BG16: White glazing | BH16: AEM
A17: OCT007.08 | B17: Tianjin | C17: OCT007 | D17: CORE DG | E17: Internal | F17: Arrival Plan-SPNL | G17: DAP | H17: SunPower Energy Solutions France SAS | I17: n/a | J17: SPTN // Baltsolar | K17: 46011059 | M17: n/a | N17: n/a | O17: Half Cut | P17: GF0700000078 | Q17: HSM-ND48-DR450 | R17: EVO2A | S17: ±1200mm | T17: 450 | U17: 1872 | V17: 0.842 | W17: 52 | X17: 2 | Y17: COMPLETED | Z17: COMPLETED | AB17: 46016 | AC17: 52 | AD17: POPV260115023 | AF17: TIANJIN | AG17: Tianjin | AH17: ROTTERDAM | AI17: 46027 | AJ17: 46027 | AK17: 46027 | AL17: 46081 | AM17: 46094 | AN17: 46094 | AO17: DAP | AP17: COSCO SHIPPING GALAXY 028W | AQ17: COSCO | AR17: TPVB20251219008 | AS17: COSU9505242760 | AT17: COSU9505242760 | AU17: 67 | AV17: SWB | AW17: 46094 | AX17: In Stock-Approved | AY17: 46097 | AZ17: 7 | BA17: 46101 | BB17: 2026 | BC17: 3 | BD17: 12 | BE17: 36 | BF17: 936 | BG17: Black glazing | BH17: AEU
A18: NOV009 | B18: Tianjin | C18: Main Line | D18: CORE DG | E18: Internal | F18: Arrival Plan-SPTN | G18: DAP | H18: SunPower Energy Solutions France SAS | I18: n/a | J18: Local WH | M18: n/a | N18: n/a | O18: Half Cut | P18: GF0700001603 | Q18: HSM-ND48-DR455_CFP | R18: EVO2A | S18: ±1200mm | T18: 455 | U18: 5616 | V18: 2.555 | W18: 156 | X18: 6 | Y18: COMPLETED | Z18: COMPLETED | AB18: 46016 | AC18: 52 | AD18: POPV260204032 | AF18: TIANJIN | AG18: Tianjin | AH18: FOS SUR MER | AI18: 46027 | AJ18: 46027 | AK18: 46027 | AL18: 46090 | AM18: 46101 | AN18: 46102 | AO18: DAP | AP18: COSCO SHIPPING GALAXY 028W | AQ18: COSCO | AR18: TPVB20251219009 | AS18: COSU6439291780 | AT18: COSU6439291780 | AU18: 75 | AV18: SWB | AW18: 46102 | AX18: In Stock-Approved | AY18: 46115 | AZ18: 8 | BA18: 46110 | BB18: 2026 | BC18: 3 | BD18: 13 | BE18: 36 | BF18: 936 | BG18: Transparent | BH18: AEM
A19: DEC009.10 | B19: Yixing | C19: DEC009 | D19: CORE DG | E19: Internal | F19: Arrival Plan-SPNL | G19: DAP | H19: SunPower Energy Solutions France SAS | I19: n/a | J19: Local WH | M19: n/a | N19: n/a | O19: P7 COM S BF IT | P19: GF0700000769 | Q19: PVM, SPR-P7-555-COM-S, I BF-G M4.3D EVO2Z6NL 1.5KV IT | R19: EVO2A | S19: ±1400mm | T19: 555 | U19: 660 | V19: 0.366 | W19: 20 | X19: 1 | Y19: COMPLETED | Z19: COMPLETED | AB19: 46028 | AC19: 2 | AD19: POPV260126026 | AF19: SHANGHAI | AG19: Shanghai | AH19: ROTTERDAM | AI19: 46031 | AJ19: 46036 | AK19: 46035 | AL19: 46069 | AM19: 46087 | AN19: 46087 | AO19: DAP | AP19: COSCO NETHERLANDS 075W | AQ19: COSCO | AR19: TPVB20260102009 | AS19: COSU6440379730 | AT19: COSU6440379730 | AU19: 52 | AW19: 46087 | AX19: In Stock-Approved | AY19: 46101 | AZ19: 7 | BA19: 46094 | BB19: 2026 | BC19: 3 | BD19: 11 | BE19: 33 | BF19: 660 | BG19: White glazing | BH19: AEU
A20: NOV017.11 | B20: Yixing | C20: NOV017 | D20: UPP | E20: Internal | F20: Arrival Plan-SPNL | G20: DAP | H20: SunPower Energy Solutions France SAS | I20: n/a | J20: SPTN / Elements Montredon | K20: FR0125122900699 | M20: n/a | N20: n/a | O20: Half Cut | P20: GF0700000313 | Q20: HSM-ND66-GR625 CFP | R20: EVO2A | S20: ±1400mm | T20: 625 | U20: 2880 | V20: 1.8 | W20: 80 | X20: 4 | Y20: COMPLETED | Z20: COMPLETED | AB20: 46028 | AC20: 2 | AD20: POPV260126028 | AF20: SHANGHAI | AG20: Shanghai | AH20: ROTTERDAM | AI20: 46033 | AJ20: 46033 | AK20: 46032 | AL20: 46070 | AM20: 46074 | AN20: 46078 | AO20: DAP | AP20: CMA CGM SAINT GERMAIN 0FMLKW1MA | AQ20: OTHER | AR20: TPVB20260102001 | AS20: CHN2962495 | AT20: CHN2962495 | AU20: 46 | AW20: 46078 | AX20: In Stock-Approved | AY20: 46090 | AZ20: 7 | BA20: 46085 | BB20: 2026 | BC20: 3 | BD20: 10 | BE20: 36 | BF20: 720 | BG20: Redirection Film | BH20: AEU
A21: NOV017.09 | B21: Yixing | C21: NOV017 | D21: UPP | E21: Internal | F21: Arrival Plan-SPNL | G21: DAP | H21: SunPower Energy Solutions France SAS | I21: n/a | J21: SPTN / Elements Montredon | K21: FR0125122900699 | M21: n/a | N21: n/a | O21: Half Cut | P21: GF0700000313 | Q21: HSM-ND66-GR625 CFP | R21: EVO2A | S21: ±1400mm | T21: 625 | U21: 5040 | V21: 3.15 | W21: 140 | X21: 7 | Y21: COMPLETED | Z21: COMPLETED | AB21: 46028 | AC21: 2 | AD21: POPV260126029 | AF21: SHANGHAI | AG21: Shanghai | AH21: ROTTERDAM | AI21: 46033 | AJ21: 46033 | AK21: 46032 | AL21: 46070 | AM21: 46074 | AN21: 46078 | AO21: DAP | AP21: CMA CGM SAINT GERMAIN 0FMLKW1MA | AQ21: OTHER | AR21: TPVB20260102001 | AS21: CHN2962495 | AT21: CHN2962495 | AU21: 46 | AW21: 46078 | AX21: In Stock-Approved | AY21: 46090 | AZ21: 7 | BA21: 46085 | BB21: 2026 | BC21: 3 | BD21: 10 | BE21: 36 | BF21: 720 | BG21: Redirection Film | BH21: AEU
A22: DEC009.01 | B22: Yixing | C22: DEC009 | D22: CORE DG | E22: Internal | F22: Arrival Plan-SPTN | G22: DAP | H22: SunPower Energy Solutions France SAS | I22: n/a | J22: Local WH | M22: n/a | N22: n/a | O22: P7 COM S BF IT | P22: GF0700000769 | Q22: PVM, SPR-P7-555-COM-S, I BF-G M4.3D EVO2Z6NL 1.5KV IT | R22: EVO2A | S22: ±1400mm | T22: 555 | U22: 1320 | V22: 0.733 | W22: 40 | X22: 2 | Y22: COMPLETED | Z22: COMPLETED | AB22: 46024 | AC22: 1 | AD22: POPV260126033 | AF22: SHANGHAI | AG22: Shanghai | AH22: FOS SUR MER | AI22: 46028 | AJ22: 46029 | AK22: 46029 | AL22: 46077 | AM22: 46083 | AN22: 46083 | AO22: DAP | AP22: CMA CGM BIG SUR 0MEMRW1MA | AQ22: COSCO | AR22: TPVB20260102003 | AS22: COSU6440380050 | AT22: COSU6440380050 | AU22: 54 | AW22: 46083 | AX22: In Stock-Approved | AY22: 46097 | AZ22: 8 | BA22: 46091 | BB22: 2026 | BC22: 3 | BD22: 11 | BE22: 33 | BF22: 660 | BG22: White glazing | BH22: AEM
A23: DEC009.06 | B23: Yixing | C23: DEC009 | D23: CORE DG | E23: Internal | F23: Arrival Plan-SPTN | G23: DAP | H23: SunPower Energy Solutions France SAS | I23: n/a | J23: Local WH - SPTN W74 | M23: n/a | N23: n/a | O23: P7 COM S BF IT | P23: GF0700000769 | Q23: PVM, SPR-P7-555-COM-S, I BF-G M4.3D EVO2Z6NL 1.5KV IT | R23: EVO2A | S23: ±1400mm | T23: 555 | U23: 1320 | V23: 0.733 | W23: 40 | X23: 2 | Y23: COMPLETED | Z23: COMPLETED | AB23: 46024 | AC23: 1 | AD23: POPV260127044 | AF23: SHANGHAI | AG23: Shanghai | AH23: FOS SUR MER | AI23: 46028 | AJ23: 46029 | AK23: 46029 | AL23: 46077 | AM23: 46083 | AN23: 46083 | AO23: DAP | AP23: CMA CGM BIG SUR | AQ23: COSCO | AR23: TPVB20260102003 | AS23: COSU6440380050 | AT23: COSU6440380050 | AU23: 54 | AW23: 46083 | AX23: In Stock-Approved | AY23: 46097 | AZ23: 8 | BA23: 46091 | BB23: 2026 | BC23: 3 | BD23: 11 | BE23: 33 | BF23: 660 | BG23: White glazing | BH23: AEM
A24: DEC003.11 | B24: Yixing | C24: DEC003 | D24: UPP | E24: Internal | F24: Arrival Plan-SPES | G24: DAP | H24: Sunpower Energy Systems Spain, S.L.U. | I24: n/a | J24: SPES / Total Portugal | K24: PT0125122900789 | M24: n/a | N24: n/a | O24: Half Cut | P24: GF0700001575 | Q24: HSM-ND78-GF640 | R24: EVO2A | S24: ±1400mm | T24: 640 | U24: 1152 | V24: 0.737 | W24: 32 | X24: 2 | Y24: COMPLETED | Z24: COMPLETED | AB24: 46024 | AC24: 1 | AD24: POPV260126030 | AF24: SHANGHAI | AG24: Shanghai | AH24: VALENCIA | AI24: 46028 | AJ24: 46029 | AK24: 46029 | AL24: 46072 | AM24: 46072 | AN24: 46075 | AO24: DAP | AP24: CMA CGM BIG SUR 0MEMRW1MA | AQ24: COSCO | AR24: TPVB20260102004 | AS24: COSU6440380240 | AT24: COSU6440380240 | AU24: 46 | AW24: 46075 | AX24: In Stock-Approved | AY24: 46086 | AZ24: 9 | BA24: 46084 | BB24: 2026 | BC24: 3 | BD24: 10 | BE24: 36 | BF24: 576 | BG24: Redirection Film | BH24: AEM
A25: DEC003.12.01 | B25: Yixing | C25: DEC003 | D25: UPP | E25: Internal | F25: Arrival Plan-SPES | G25: DAP | H25: Sunpower Energy Systems Spain, S.L.U. | I25: n/a | J25: SPES / Total Portugal | K25: PT0125122900789 | M25: n/a | N25: n/a | O25: Half Cut | P25: GF0700001575 | Q25: HSM-ND78-GF640 | R25: EVO2A | S25: ±1400mm | T25: 640 | U25: 967 | V25: 0.619 | W25: 26.9 | X25: 1.7 | Y25: COMPLETED | Z25: COMPLETED | AB25: 46027 | AC25: 2 | AD25: POPV260126032 | AF25: SHANGHAI | AG25: Shanghai | AH25: VALENCIA | AI25: 46032 | AJ25: 45670 | AK25: 46035 | AL25: 46072 | AM25: 46076 | AN25: 46078 | AO25: DAP | AP25: CSCL MERCURY 098W | AQ25: COSCO | AR25: TPVB20260102005 | AS25: COSU6440381610 | AT25: COSU6440381610 | AU25: 43 | AW25: 46078 | AX25: In Stock-Approved | AY25: 46092 | AZ25: 9 | BA25: 46087 | BB25: 2026 | BC25: 3 | BD25: 10 | BE25: 36 | BF25: 576 | BG25: Redirection Film | BH25: AEM
A26: DEC003.12 | B26: Yixing | C26: DEC003 | D26: UPP | E26: Internal | F26: Arrival Plan-SPES | G26: DAP | H26: Sunpower Energy Systems Spain, S.L.U. | I26: n/a | J26: SPES / Total Portugal | K26: PT0125122900789 | M26: n/a | N26: n/a | O26: Half Cut | P26: GF0700001575 | Q26: HSM-ND78-GF640 | R26: EVO2A | S26: ±1400mm | T26: 640 | U26: 761 | V26: 0.487 | W26: 21.1 | X26: 1.3 | Y26: COMPLETED | Z26: COMPLETED | AB26: 46027 | AC26: 2 | AD26: POPV260126032 | AF26: SHANGHAI | AG26: Shanghai | AH26: VALENCIA | AI26: 46032 | AJ26: 45670 | AK26: 46035 | AL26: 46072 | AM26: 46076 | AN26: 46078 | AO26: DAP | AP26: CSCL MERCURY 098W | AQ26: COSCO | AR26: TPVB20260102005 | AS26: COSU6440381610 | AT26: COSU6440381610 | AU26: 43 | AW26: 46078 | AX26: In Stock-Approved | AY26: 46092 | AZ26: 9 | BA26: 46087 | BB26: 2026 | BC26: 3 | BD26: 10 | BE26: 36 | BF26: 576 | BG26: Redirection Film | BH26: AEM
A27: DEC003.13 | B27: Yixing | C27: DEC003 | D27: UPP | E27: Internal | F27: Arrival Plan-SPES | G27: DAP | H27: Sunpower Energy Systems Spain, S.L.U. | I27: n/a | J27: SPES / Total Portugal | K27: PT0125122900789 | M27: n/a | N27: n/a | O27: Half Cut | P27: GF0700001575 | Q27: HSM-ND78-GF640 | R27: EVO2A | S27: ±1400mm | T27: 640 | U27: 1728 | V27: 1.106 | W27: 48 | X27: 3 | Y27: COMPLETED | Z27: COMPLETED | AB27: 46026 | AC27: 1 | AD27: POPV260206008 | AF27: SHANGHAI | AG27: Shanghai | AH27: VALENCIA | AI27: 46031 | AK27: 46030 | AL27: 46086 | AM27: 46088 | AN27: 46089 | AO27: DAP | AP27: COSCO SHIPPING SCORPIO 033W | AQ27: COSCO | AR27: TPVB20260102006 | AS27: COSU6440381320 | AT27: COSU6440381320 | AU27: 59 | AW27: 46089 | AX27: In Stock-Approved | AY27: 46100 | AZ27: 9 | BA27: 46098 | BB27: 2026 | BC27: 3 | BD27: 12 | BE27: 36 | BF27: 576 | BG27: Redirection Film | BH27: AEM
A28: NOV005.03 | B28: Yixing | C28: NOV005 | D28: CORE DG | E28: Internal | F28: Arrival Plan-SPTN | G28: DAP | H28: SunPower Energy Solutions France SAS | I28: n/a | J28: Distributors Italy - SPTN W74 | M28: n/a | N28: n/a | O28: Shingle | P28: GF0700001578 | Q28: TCL-MR465DT182-58NS | R28: EVO2A | S28: ±1200mm | T28: 465 | U28: 1728 | V28: 0.804 | W28: 48 | X28: 2 | Y28: COMPLETED | Z28: COMPLETED | AB28: 46026 | AC28: 1 | AD28: POPV260224032 | AF28: SHANGHAI | AG28: Shanghai | AH28: FOS SUR MER | AI28: 46031 | AK28: 46030 | AL28: 46078 | AM28: 46083 | AN28: 46084 | AO28: DAP | AP28: COSCO SHIPPING SCORPIO 033W | AQ28: COSCO | AR28: TPVB20260102007 | AS28: COSU6440242670 | AT28: COSU6440242670 | AU28: 54 | AW28: 46084 | AX28: In Stock-Approved | AY28: 46097 | AZ28: 8 | BA28: 46092 | BB28: 2026 | BC28: 3 | BD28: 11 | BE28: 36 | BF28: 864 | BG28: White glazing | BH28: AEM
A29: NOV005.04 | B29: Yixing | C29: NOV005 | D29: CORE DG | E29: Internal | F29: Arrival Plan-SPNL | G29: DAP | H29: SunPower Energy Solutions France SAS | I29: n/a | J29: Distributors Italy - W72 | M29: n/a | N29: n/a | O29: Shingle | P29: GF0700001578 | Q29: TCL-MR465DT182-58NS | R29: EVO2A | S29: ±1200mm | T29: 465 | U29: 864 | V29: 0.402 | W29: 24 | X29: 1 | Y29: COMPLETED | Z29: COMPLETED | AB29: 46026 | AC29: 1 | AD29: POPV260417059 | AF29: SHANGHAI | AG29: Shanghai | AH29: ROTTERDAM | AI29: 46031 | AK29: 46030 | AL29: 46080 | AM29: 46111 | AN29: 46111 | AO29: DAP | AP29: COSCO SHIPPING SCORPIO 033W | AQ29: COSCO | AR29: TPVB20260102008 | AS29: COSU6440242960 | AT29: COSU6440242960 | AU29: 81 | AW29: 46111 | AX29: In Stock-Approved | AY29: 46146 | AZ29: 7 | BA29: 46118 | BB29: 2026 | BC29: 4 | BD29: 15 | BE29: 36 | BF29: 864 | BG29: White glazing | BH29: AEU
A30: DEC009.04 | B30: Yixing | C30: DEC009 | D30: CORE DG | E30: Internal | F30: Arrival Plan-SPNL | G30: DAP | H30: SunPower Energy Solutions France SAS | I30: n/a | J30: Local WH - W72 (Italy) | M30: n/a | N30: n/a | O30: P7 COM S BF IT | P30: GF0700000769 | Q30: PVM, SPR-P7-555-COM-S, I BF-G M4.3D EVO2Z6NL 1.5KV IT | R30: EVO2A | S30: ±1400mm | T30: 555 | U30: 660 | V30: 0.366 | W30: 20 | X30: 1 | Y30: COMPLETED | Z30: COMPLETED | AB30: 46026 | AC30: 1 | AD30: POPV260217039 | AF30: SHANGHAI | AG30: Shanghai | AH30: ROTTERDAM | AI30: 46031 | AK30: 46030 | AL30: 46080 | AM30: 46111 | AN30: 46111 | AO30: DAP | AP30: COSCO SHIPPING SCORPIO 033W | AQ30: COSCO | AR30: TPVB20260102008 | AS30: COSU6440242960 | AT30: COSU6440242960 | AU30: 81 | AW30: 46111 | AX30: In Stock-Approved | AY30: 46125 | AZ30: 7 | BA30: 46118 | BB30: 2026 | BC30: 4 | BD30: 15 | BE30: 33 | BF30: 660 | BG30: White glazing | BH30: AEU
A31: DEC009.11 | B31: Yixing | C31: DEC009 | D31: CORE DG | E31: Internal | F31: Arrival Plan-SPNL | G31: DAP | H31: SunPower Energy Solutions France SAS | I31: n/a | J31: Local WH | M31: n/a | N31: n/a | O31: P7 COM S BF IT | P31: GF0700000769 | Q31: PVM, SPR-P7-555-COM-S, I BF-G M4.3D EVO2Z6NL 1.5KV IT | R31: EVO2A | S31: ±1400mm | T31: 555 | U31: 1320 | V31: 0.733 | W31: 40 | X31: 2 | Y31: COMPLETED | Z31: COMPLETED | AB31: 46029 | AC31: 2 | AD31: POPV260126031 | AF31: SHANGHAI | AG31: Shanghai | AH31: ROTTERDAM | AI31: 46035 | AJ31: 46037 | AK31: 46037 | AL31: 46071 | AM31: 46083 | AN31: 46083 | AO31: DAP | AP31: EVER APEX 1383-013W | AQ31: COSCO | AR31: TPVB20260109002 | AS31: COSU6441128810 | AT31: COSU6441128810 | AU31: 46 | AW31: 46083 | AX31: In Stock-Approved | AY31: 46097 | AZ31: 7 | BA31: 46090 | BB31: 2026 | BC31: 3 | BD31: 11 | BE31: 33 | BF31: 660 | BG31: White glazing | BH31: AEU
A32: DEC003.06 | B32: Yixing | C32: DEC003 | D32: UPP | E32: Internal | F32: Arrival Plan-SPES | G32: DAP | H32: Sunpower Energy Systems Spain, S.L.U. | I32: n/a | J32: SPES / Total Portugal | K32: PT0125122900795 | M32: n/a | N32: n/a | O32: Half Cut | P32: GF0700001575 | Q32: HSM-ND78-GF640 | R32: EVO2A | S32: ±1400mm | T32: 640 | U32: 1152 | V32: 0.737 | W32: 32 | X32: 2 | Y32: COMPLETED | Z32: COMPLETED | AB32: 46034 | AC32: 3 | AD32: POPV260206007 | AF32: SHANGHAI | AG32: Shanghai | AH32: VALENCIA | AI32: 46042 | AJ32: 46044 | AK32: 46044 | AL32: 46081 | AM32: 46083 | AN32: 46084 | AO32: DAP | AP32: CSCL SATURN 087W | AQ32: COSCO | AR32: TPVB20260109003 | AS32: COSU6441114300 | AT32: COSU6441114300 | AU32: 40 | AW32: 46084 | AX32: In Stock-Approved | AY32: 46095 | AZ32: 9 | BA32: 46093 | BB32: 2026 | BC32: 3 | BD32: 11 | BE32: 36 | BF32: 576 | BG32: Redirection Film | BH32: AEM
A33: DEC003.05 | B33: Yixing | C33: DEC003 | D33: UPP | E33: Internal | F33: Arrival Plan-SPES | G33: DAP | H33: Sunpower Energy Systems Spain, S.L.U. | I33: n/a | J33: SPES / Total Portugal | K33: PT0125122900789 | M33: n/a | N33: n/a | O33: Half Cut | P33: GF0700001575 | Q33: HSM-ND78-GF640 | R33: EVO2A | S33: ±1400mm | T33: 640 | U33: 2124 | V33: 1.359 | W33: 59 | X33: 3.7 | Y33: COMPLETED | Z33: COMPLETED | AB33: 46029 | AC33: 2 | AD33: POPV260129005 | AF33: SHANGHAI | AG33: Shanghai | AH33: VALENCIA | AI33: 46035 | AJ33: 46041 | AK33: 46041 | AL33: 46079 | AM33: 46079 | AN33: 46079 | AO33: DAP | AP33: CMA CGM CEDRUS 0MEMTW1MA | AQ33: COSCO | AR33: TPVB20260109004 | AS33: COSU6440662920 | AT33: COSU6440662920 | AU33: 38 | AW33: 46079 | AX33: In Stock-Approved | AY33: 46093 | AZ33: 9 | BA33: 46088 | BB33: 2026 | BC33: 3 | BD33: 10 | BE33: 36 | BF33: 576 | BG33: Redirection Film | BH33: AEM
A34: DEC003.10 | B34: Yixing | C34: DEC003 | D34: UPP | E34: Internal | F34: Arrival Plan-SPES | G34: DAP | H34: Sunpower Energy Systems Spain, S.L.U. | I34: n/a | J34: SPES / Total Portugal | K34: PT0125122900795 | M34: n/a | N34: n/a | O34: Half Cut | P34: GF0700001575 | Q34: HSM-ND78-GF640 | R34: EVO2A | S34: ±1400mm | T34: 640 | U34: 180 | V34: 0.115 | W34: 5 | X34: 0.3 | Y34: COMPLETED | Z34: COMPLETED | AB34: 46029 | AC34: 2 | AD34: POPV260129004 | AF34: SHANGHAI | AG34: Shanghai | AH34: VALENCIA | AI34: 46035 | AJ34: 46041 | AK34: 46041 | AL34: 46079 | AM34: 46079 | AN34: 46079 | AO34: DAP | AP34: CMA CGM CEDRUS 0MEMTW1MA | AQ34: COSCO | AR34: TPVB20260109004 | AS34: COSU6440662920 | AT34: COSU6440662920 | AU34: 38 | AW34: 46079 | AX34: In Stock-Approved | AY34: 46093 | AZ34: 9 | BA34: 46088 | BB34: 2026 | BC34: 3 | BD34: 10 | BE34: 36 | BF34: 576 | BG34: Redirection Film | BH34: AEM
A35: DEC003.15 | B35: Yixing | C35: DEC003 | D35: UPP | E35: Internal | F35: Arrival Plan-SPES | G35: DAP | H35: Sunpower Energy Systems Spain, S.L.U. | I35: n/a | J35: SPES / Total Portugal | K35: PT0125122900795 | M35: n/a | N35: n/a | O35: Half Cut | P35: GF0700001575 | Q35: HSM-ND78-GF640 | R35: EVO2A | S35: ±1400mm | T35: 640 | U35: 1152 | V35: 0.737 | W35: 32 | X35: 2 | Y35: COMPLETED | Z35: COMPLETED | AB35: 46029 | AC35: 2 | AD35: POPV260129012 | AF35: SHANGHAI | AG35: Shanghai | AH35: VALENCIA | AI35: 46035 | AJ35: 46041 | AK35: 46041 | AL35: 46079 | AM35: 46079 | AN35: 46079 | AO35: DAP | AP35: CMA CGM CEDRUS 0MEMTW1MA | AQ35: COSCO | AR35: TPVB20260109004 | AS35: COSU6440662920 | AT35: COSU6440662920 | AU35: 38 | AW35: 46079 | AX35: In Stock-Approved | AY35: 46093 | AZ35: 9 | BA35: 46088 | BB35: 2026 | BC35: 3 | BD35: 10 | BE35: 36 | BF35: 576 | BG35: Redirection Film | BH35: AEM
A36: JUNE001.09 | B36: zhuhai -> Shenzhen | C36: JUNE001 | D36: CORE DG | E36: Internal | F36: Arrival Plan-SPNL | G36: DAP | H36: SunPower Energy Solutions France SAS | I36: n/a | J36: SPTN / Grosshandelsunion | M36: n/a | N36: n/a | O36: BC | P36: GF0700000075 | Q36: HSM-BD54-DA460 | R36: EVO2A | S36: ±1400mm | T36: 460 | U36: 962 | V36: 0.443 | W36: 26 | X36: 1 | Y36: COMPLETED | Z36: COMPLETED | AB36: 46030 | AC36: 2 | AD36: POPV260126025 | AF36: SHENZHEN | AG36: Shenzhen | AH36: ROTTERDAM | AI36: 46038 | AJ36: 46041 | AK36: 46041 | AL36: 46069 | AM36: 46087 | AN36: 46087 | AO36: DAP | AP36: COSCO NETHERLANDS 075W | AQ36: COSCO | AR36: TPVB20260109005 | AS36: COSU6440518510 | AT36: COSU6440518510 | AU36: 46 | AV36: SWB | AW36: 46087 | AX36: In Stock-Approved | AY36: 46094 | AZ36: 7 | BA36: 46094 | BB36: 2026 | BC36: 3 | BD36: 11 | BE36: 37 | BF36: 962 | BG36: Black glazing | BH36: AEU
A37: JUNE001.11 | B37: zhuhai -> Shenzhen | C37: JUNE001 | D37: CORE DG | E37: Internal | F37: Arrival Plan-SPNL | G37: DAP | H37: SunPower Energy Solutions France SAS | I37: n/a | J37: SPTN / Energy3000 | M37: n/a | N37: n/a | O37: BC | P37: GF0700000075 | Q37: HSM-BD54-DA460 | R37: EVO2A | S37: ±1400mm | T37: 460 | U37: 4810 | V37: 2.213 | W37: 130 | X37: 5 | Y37: COMPLETED | Z37: COMPLETED | AB37: 46030 | AC37: 2 | AD37: POPV260126022 | AF37: SHENZHEN | AG37: Shenzhen | AH37: ROTTERDAM | AI37: 46038 | AJ37: 46041 | AK37: 46041 | AL37: 46069 | AM37: 46087 | AN37: 46087 | AO37: DAP | AP37: COSCO NETHERLANDS 075W | AQ37: COSCO | AR37: TPVB20260109005 | AS37: COSU6440518510 | AT37: COSU6440518510 | AU37: 46 | AV37: SWB | AW37: 46087 | AX37: In Stock-Approved | AY37: 46094 | AZ37: 7 | BA37: 46094 | BB37: 2026 | BC37: 3 | BD37: 11 | BE37: 37 | BF37: 962 | BG37: Black glazing | BH37: AEU
A38: DEC001.01 | B38: Zhuhai | C38: DEC001 | D38: CORE DG | E38: Internal | F38: Arrival Plan-SPNL | G38: DAP | H38: SunPower Energy Solutions France SAS | I38: n/a | J38: Local WH | M38: n/a | N38: n/a | O38: M Class | P38: GF0700000804 | Q38: SPR-BE54-DC480 | R38: EVO2A | S38: ±1200mm | T38: 480 | U38: 1924 | V38: 0.924 | W38: 52 | X38: 2 | Y38: COMPLETED | Z38: COMPLETED | AB38: 46031 | AC38: 2 | AD38: POPV260126023 | AF38: SHENZHEN | AG38: Shenzhen | AH38: ROTTERDAM | AI38: 46038 | AJ38: 46041 | AK38: 46041 | AL38: 46069 | AM38: 46087 | AN38: 46087 | AO38: DAP | AP38: COSCO NETHERLANDS 075W | AQ38: COSCO | AR38: TPVB20260109006 | AS38: COSU6440518511 | AT38: COSU6440518511 | AU38: 46 | AV38: SWB | AW38: 46087 | AX38: In Stock-Approved | AY38: 46101 | AZ38: 7 | BA38: 46094 | BB38: 2026 | BC38: 3 | BD38: 11 | BE38: 37 | BF38: 962 | BG38: Black glazing | BH38: AEU
A39: DEC002.01 | B39: Zhuhai | C39: DEC002 | D39: CORE DG | E39: Internal | F39: Arrival Plan-SPNL | G39: DAP | H39: SunPower Energy Solutions France SAS | I39: n/a | J39: Local WH | M39: n/a | N39: n/a | O39: M Class | P39: GF0700000805 | Q39: SPR-BE54-DC485 | R39: EVO2A | S39: ±1200mm | T39: 485 | U39: 2886 | V39: 1.4 | W39: 78 | X39: 3 | Y39: COMPLETED | Z39: COMPLETED | AB39: 46031 | AC39: 2 | AD39: POPV260126027 | AF39: SHENZHEN | AG39: Shenzhen | AH39: ROTTERDAM | AI39: 46038 | AJ39: 46041 | AK39: 46041 | AL39: 46069 | AM39: 46087 | AN39: 46087 | AO39: DAP | AP39: COSCO NETHERLANDS 075W | AQ39: COSCO | AR39: TPVB20260109006 | AS39: COSU6440518511 | AT39: COSU6440518511 | AU39: 46 | AV39: SWB | AW39: 46087 | AX39: In Stock-Approved | AY39: 46101 | AZ39: 7 | BA39: 46094 | BB39: 2026 | BC39: 3 | BD39: 11 | BE39: 37 | BF39: 962 | BG39: Black glazing | BH39: AEU
A40: DEC001.02 | B40: Zhuhai | C40: DEC001 | D40: CORE DG | E40: Internal | F40: Arrival Plan-SPIT | G40: DAP | H40: Sunpower Italia S.R.L. | I40: n/a | J40: Local WH - POD to be updated vs. W81 | M40: n/a | N40: n/a | O40: M Class | P40: GF0700000804 | Q40: SPR-BE54-DC480 | R40: EVO2A | S40: ±1200mm | T40: 480 | U40: 1924 | V40: 0.924 | W40: 52 | X40: 2 | Y40: COMPLETED | Z40: COMPLETED | AB40: 46034 | AC40: 3 | AD40: POPV260129008 | AF40: SHENZHEN | AG40: Shenzhen | AH40: GENOA | AI40: 46037 | AJ40: 46037 | AK40: 46038 | AL40: 46078 | AM40: 46078 | AN40: 46078 | AO40: DAP | AP40: COSCO SHIPPING SCORPIO 033W | AQ40: COSCO | AR40: TPVB20260109007 | AS40: COSU6440775660 | AT40: COSU6440775660 | AU40: 40 | AV40: SWB | AW40: 46078 | AX40: In Stock-Approved | AY40: 46092 | AZ40: 13 | BA40: 46091 | BB40: 2026 | BC40: 3 | BD40: 11 | BE40: 37 | BF40: 962 | BG40: Black glazing | BH40: AEM
...

Sheet H2-2025 PV DATA
A1: TCL REFERENCE NO. | B1: Factory Location | C1: FX_QTY criteria | D1: CHANNEL | E1: New Ark PO Type | F1: New Ark WH | G1: B/L Consignee | H1: TCL-HK PO INCOTERM Requested | I1: ALLOCATION Planning | J1: Priority Level | K1: SPWR SO Number | L1: Region | M1: G2G ? | N1: Factory Available Date | O1: ATP Status | P1: PRODUCT TYPE | Q1: New Ark SKU | R1: Oracle SKU | S1: DESCRIPTION | T1: WATT | U1: QUANTITY | V1: MW | W1: PALLETS | X1: CONTAINERS | Y1: STATUS | Z1: ship before 4.1? | AA1: Back Glass | AB1: Cable Length | AC1: Pick-Up Date | AD1: Pick-Up Week | AE1: SPTN-PVHK New Ark PO# | AF1: SPTN-HKPV ORacle PO# | AG1: PORT OF LOADING | AH1: PORT DESTINATION | AI1: ETD On S/O | AJ1: ETD Update | AK1: ATD PORT | AL1: ETA On S/O | AM1: ETA Update | AN1: ATA PORT | AO1: incoterm | AP1: REFERENCE V.V | AQ1: Carrier | AR1: TCL Invoice# or PO# | AS1: MBL/HBL# | AT1: Booking # | AU1: Leg2 leadtime On S/O | AV1: Telex released | AW1: TBA - 1 | AX1: LT (pick-up to ETA) | AY1: ETD Conso | AZ1: ODP Available Port | BA1: New Ark PO status | BB1: New Ark ETA | BC1: ETA WH / Port for New Ark | BD1: ETA WH Year | BE1: ETA WH Month | BF1: ETA WH Week | BG1: Qty/Pallet | BH1: Qty/CT
A2: MAY006.17 | C2: MAY006 | D2: CORE DG | E2: Internal | F2: Arrival Plan-SPTN | G2: SunPower Energy Solutions France SAS | H2: DAP | I2: Local WH | J2: n/a | L2: All | M2: n/a | O2: Check Availability in New Ark | P2: P7 COM S BF IT | Q2: GF0700000769 | R2: 552045 | S2: PVM, SPR-P7-555-COM-S, I BF-G M4.3D EVO2Z6NL 1.5KV IT | T2: 555 | U2: 1980 | V2: 1.0989 | W2: 60 | X2: 3 | Y2: COMPLETED | AA2: White glazing | AB2: ±1400mm | AC2: 45814 | AD2: 23 | AE2: POPV251231059 | AF2: 371008554 | AG2: SHANGHAI | AH2: FOS SUR MER | AI2: 45822 | AJ2: 45822 | AK2: 45822 | AL2: 45872 | AM2: 45873 | AN2: 45872 | AO2: DAP | AP2: CMA CGM KIMBERLEY/0MEL3W1MA | AR2: TPVB20250529001 | AS2: COSU6419461300 | AT2: COSU6419461300 | AU2: 51 | AV2: SWB | AW2: 11 | AX2: 58 | AY2: 45822 | AZ2: 45872 | BA2: #N/A | BC2: 45886 | BD2: 2025 | BE2: 8 | BF2: 33 | BG2: 33 | BH2: 660
A3: MAY006.18 | C3: MAY006 | D3: CORE DG | E3: n/a | F3: n/a | H3: DAP | I3: Local WH | J3: n/a | L3: lberia Region | M3: n/a | O3: Check Availability in New Ark | P3: P7 COM S BF IT | Q3: GF0700000769 | R3: 552045 | S3: PVM, SPR-P7-555-COM-S, I BF-G M4.3D EVO2Z6NL 1.5KV IT | T3: 555 | U3: 660 | V3: 0.3663 | W3: 20 | X3: 1 | Y3: COMPLETED | AA3: White glazing | AB3: ±1400mm | AC3: 45814 | AD3: 23 | AE3: POPV251231053 | AF3: 371008559 | AG3: SHANGHAI | AH3: VALENCIA | AI3: 45819 | AJ3: 45819 | AK3: 45819 | AL3: 45866 | AM3: 45866 | AN3: 45866 | AO3: DAP | AP3: CSCL MERCURY/096W | AR3: TPVB20250529008 | AS3: COSU6419474470 | AT3: COSU6419474470 | AU3: 48 | AV3: SWB | AW3: 11 | AX3: 52 | AY3: 45819 | AZ3: 45866 | BA3: #N/A | BC3: 45880 | BD3: 2025 | BE3: 8 | BF3: 33 | BG3: 33 | BH3: 660
A4: MAY006.19 | C4: MAY006 | D4: CORE DG | E4: n/a | F4: n/a | H4: CIP | I4: Reenpro | J4: n/a | L4: Emerging Market | M4: n/a | O4: Check Availability in New Ark | P4: P7 COM S BF IT | Q4: GF0700000769 | R4: 552045 | S4: PVM, SPR-P7-555-COM-S, I BF-G M4.3D EVO2Z6NL 1.5KV IT | T4: 555 | U4: 1980 | V4: 1.0989 | W4: 60 | X4: 3 | Y4: COMPLETED | AA4: White glazing | AB4: ±1400mm | AC4: 45815 | AD4: 23 | AE4: POPV251231056 | AF4: 371008556 | AG4: SHANGHAI | AH4: KLAIPEDA | AI4: 45821 | AJ4: 45821 | AK4: 45821 | AL4: 45883 | AM4: 45872 | AN4: 45883 | AO4: CIP | AP4: WILHELMSHAVEN EXPR524W | AR4: 46010580-1 | AS4: 254396324 | AT4: 254396324 | AU4: 63 | AV4: Y | AW4: 11 | AX4: 68 | AY4: 45821 | AZ4: 45883 | BA4: #N/A | BC4: 45897 | BD4: 2025 | BE4: 8 | BF4: 35 | BG4: 33 | BH4: 660
A5: MAY009.01 | C5: MAY009 | D5: CORE DG | E5: n/a | F5: n/a | H5: DAP | I5: Italy Distrib. | J5: n/a | L5: Italy & Adriatics Region | M5: n/a | O5: Check Availability in New Ark | P5: Shingle | Q5: GF0700000025 | R5: 554541 | S5: TCL-MR460DT182-58NS | T5: 460 | U5: 2592 | V5: 1.19232 | W5: 72 | X5: 3 | Y5: COMPLETED | AA5: White glazing | AB5: ±1200mm | AC5: 45814 | AD5: 23 | AE5: POPV251231062 | AF5: 371008562 | AG5: SHANGHAI | AH5: GENOA | AI5: 45821 | AJ5: 45821 | AK5: 45821 | AL5: 45877 | AM5: 45872 | AN5: 45877 | AO5: DAP | AP5: EVER GENTLE/0704-025W | AR5: TPVB20250529002 | AS5: COSU6419461600 | AT5: COSU6419461600 | AU5: 57 | AV5: SWB | AW5: 6 | AX5: 63 | AY5: 45821 | AZ5: 45877 | BA5: #N/A | BC5: 45891 | BD5: 2025 | BE5: 8 | BF5: 34 | BG5: 36 | BH5: 864
A6: MAY008.01 | B6: Yixing | C6: MAY008 | D6: CORE DG | E6: n/a | F6: n/a | H6: DAP | I6: SPIT / MARINI-PANDOLFI | J6: n/a | K6: 19142931 | L6: Italy & Adriatics Region | M6: n/a | O6: Check Availability in New Ark | P6: Shingle | Q6: GF0700001780 | R6: 554431 | S6: TCL-MR455DT182-58NS | T6: 455 | U6: 1728 | V6: 0.78624 | W6: 48 | X6: 2 | Y6: COMPLETED | AA6: White glazing | AB6: ±1400mm | AC6: 45816 | AD6: 23 | AE6: POPV251231067 | AF6: 371008573 | AG6: SHANGHAI | AH6: GENOA | AI6: 45821 | AJ6: 45821 | AK6: 45821 | AL6: 45877 | AM6: 45872 | AN6: 45877 | AO6: DAP | AP6: EVER GENTLE/0704-025W | AR6: TPVB20250529007 | AS6: COSU6420662030 | AT6: COSU6420662030 | AU6: 57 | AV6: SWB | AW6: 4 | AX6: 61 | AY6: 45821 | AZ6: 45877 | BA6: #N/A | BC6: 45891 | BD6: 2025 | BE6: 8 | BF6: 34 | BG6: 36 | BH6: 864
A7: JULY004.08 | B7: Yixing | C7: JULY004 | D7: CORE DG | E7: Internal | F7: Arrival Plan-SPTN | G7: SunPower Energy Solutions France SAS | H7: DAP | I7: Local WH | J7: n/a | L7: All | M7: n/a | O7: Check Availability in New Ark | P7: Shingle | Q7: GF0700000766 | R7: 552026 | S7: PVM, SPR-P7-550-COM-S, I BF-G M4.3D EVO2Z6NL 1.5KV IT | T7: 550 | U7: 660 | V7: 0.363 | W7: 20 | X7: 1 | Y7: COMPLETED | AA7: White glazing | AB7: ±1500mm | AC7: 45814 | AD7: 23 | AE7: POPV251231059 | AF7: 371008554 | AG7: SHANGHAI | AH7: FOS SUR MER | AI7: 45822 | AJ7: 45822 | AK7: 45822 | AL7: 45872 | AM7: 45873 | AN7: 45872 | AO7: DAP | AP7: CMA CGM KIMBERLEY/0MEL3W1MA | AR7: TPVB20250529001 | AS7: COSU6419461300 | AT7: COSU6419461300 | AU7: 51 | AV7: SWB | AW7: 8 | AX7: 58 | AY7: 45822 | AZ7: 45872 | BA7: #N/A | BC7: 45886 | BD7: 2025 | BE7: 8 | BF7: 33 | BG7: 33 | BH7: 660
A8: MAY006.20 | C8: MAY006 | D8: CORE DG | E8: n/a | F8: n/a | H8: DAP | I8: Local WH - SPIT W81 | J8: n/a | L8: Italy & Adriatics Region | M8: n/a | O8: Check Availability in New Ark | P8: P7 COM S BF IT | Q8: GF0700000769 | R8: 552045 | S8: PVM, SPR-P7-555-COM-S, I BF-G M4.3D EVO2Z6NL 1.5KV IT | T8: 555 | U8: 1980 | V8: 1.0989 | W8: 60 | X8: 3 | Y8: COMPLETED | AA8: White glazing | AB8: ±1400mm | AC8: 45822 | AD8: 24 | AE8: POPV251231058 | AF8: 371008563 | AG8: SHANGHAI | AH8: GENOA | AI8: 45831 | AJ8: 45831 | AK8: 45831 | AL8: 45887 | AM8: 45886 | AN8: 45887 | AO8: DAP | AP8: COSCO SHIPPING SOLAR/033W | AR8: TPVB20250605001 | AS8: COSU6420263970 | AT8: COSU6420263970 | AU8: 57 | AV8: SWB | AW8: 11 | AX8: 65 | AY8: 45831 | AZ8: 45887 | BA8: #N/A | BC8: 45901 | BD8: 2025 | BE8: 9 | BF8: 36 | BG8: 33 | BH8: 660
A9: MAY006.21 | C9: MAY006 | D9: CORE DG | E9: n/a | F9: n/a | H9: CIP | I9: Reenpro | J9: n/a | L9: Emerging Market | M9: n/a | O9: Check Availability in New Ark | P9: P7 COM S BF IT | Q9: GF0700000769 | R9: 552045 | S9: PVM, SPR-P7-555-COM-S, I BF-G M4.3D EVO2Z6NL 1.5KV IT | T9: 555 | U9: 1320 | V9: 0.7326 | W9: 40 | X9: 2 | Y9: COMPLETED | AA9: White glazing | AB9: ±1400mm | AC9: 45822 | AD9: 24 | AE9: POPV251231072 | AF9: 371008564 | AG9: SHANGHAI | AH9: KLAIPEDA | AI9: 45828 | AJ9: 45828 | AK9: 45828 | AL9: 45883 | AM9: 45879 | AN9: 45883 | AO9: CIP | AP9: TIHAMA 525W | AR9: 46010580-2 | AS9: 255195702 | AT9: 254738544 | AU9: 56 | AV9: Y | AW9: 11 | AX9: 61 | AY9: 45828 | AZ9: 45883 | BA9: #N/A | BC9: 45897 | BD9: 2025 | BE9: 8 | BF9: 35 | BG9: 33 | BH9: 660
A10: MAY009.05 | C10: MAY009 | D10: CORE DG | E10: n/a | F10: n/a | H10: DAP | I10: Italy Distrib. | J10: n/a | L10: Italy & Adriatics Region | M10: n/a | O10: Check Availability in New Ark | P10: Shingle | Q10: GF0700000025 | R10: 554541 | S10: TCL-MR460DT182-58NS | T10: 460 | U10: 1728 | V10: 0.79488 | W10: 48 | X10: 2 | Y10: COMPLETED | AA10: White glazing | AB10: ±1200mm | AC10: 45817 | AD10: 24 | AE10: POPV251231075 | AF10: 371008571 | AG10: SHANGHAI | AH10: GENOA | AI10: 45821 | AJ10: 45821 | AK10: 45821 | AL10: 45877 | AM10: 45872 | AN10: 45877 | AO10: DAP | AP10: EVER GENTLE/0704-025W | AR10: TPVB20250529006 | AS10: COSU6420591050 | AT10: COSU6420591050 | AU10: 57 | AV10: SWB | AW10: 6 | AX10: 60 | AY10: 45821 | AZ10: 45877 | BA10: #N/A | BC10: 45891 | BD10: 2025 | BE10: 8 | BF10: 34 | BG10: 36 | BH10: 864
A11: MAY009.07 | C11: MAY009 | D11: CORE DG | E11: n/a | F11: n/a | H11: DAP | I11: Local WH - SPIT W82 | J11: n/a | L11: Italy & Adriatics Region | M11: n/a | O11: Check Availability in New Ark | P11: Shingle | Q11: GF0700000025 | R11: 554541 | S11: TCL-MR460DT182-58NS | T11: 460 | U11: 3456 | V11: 1.58976 | W11: 96 | X11: 4 | Y11: COMPLETED | AA11: White glazing | AB11: ±1200mm | AC11: 45823 | AD11: 24 | AE11: POPV251231095 | AF11: 371008572 | AG11: SHANGHAI | AH11: NAPLES | AI11: 45831 | AJ11: 45831 | AK11: 45831 | AL11: 45878 | AM11: 45878 | AN11: 45878 | AO11: DAP | AP11: COSCO SHIPPING SOLAR/033W | AR11: TPVB20250605002 | AS11: COSU6420264270 | AT11: COSU6420264270 | AU11: 48 | AV11: SWB | AW11: 6 | AX11: 55 | AY11: 45831 | AZ11: 45878 | BA11: #N/A | BC11: 45892 | BD11: 2025 | BE11: 8 | BF11: 34 | BG11: 36 | BH11: 864
A12: MAY011.01 | C12: MAY011 | D12: CORE DG | E12: n/a | F12: n/a | H12: CIF | I12: LM Eight | J12: n/a | L12: Iberia Region | M12: n/a | O12: Not Available | P12: Shingle | Q12: GF0700000023 | R12: 554542 | S12: TCL-MR515DT182-64NS | T12: 515 | U12: 1584 | V12: 0.81576 | W12: 44 | X12: 2 | Y12: COMPLETED | AA12: White glazing | AB12: ±1400mm | AC12: 45821 | AD12: 24 | AE12: n/a - 2025 legacy | AF12: TPVO2025061617 | AG12: SHANGHAI | AH12: VALENCIA | AI12: 45825 | AJ12: 45825 | AK12: 45825 | AL12: 45869 | AM12: 45869 | AN12: 45869 | AO12: CIF | AP12: COSCO SHIPPING HIMALAYAS/044W | AR12: TPVB20250605003 | AS12: COSU6420290820 | AT12: COSU6420290820 | AU12: 45 | AV12: Y | AW12: 5 | AX12: 48 | AY12: 45825 | AZ12: 45869 | BA12: #N/A | BC12: 45883 | BD12: 2025 | BE12: 8 | BF12: 33 | BG12: 36 | BH12: 792
A13: MAY011.02 | C13: MAY011 | D13: CORE DG | E13: n/a | F13: n/a | H13: CIP | I13: Reenpro | J13: n/a | L13: Emerging Market | M13: n/a | O13: Check Availability in New Ark | P13: Shingle | Q13: GF0700000023 | R13: 554542 | S13: TCL-MR515DT182-64NS | T13: 515 | U13: 792 | V13: 0.40788 | W13: 22 | X13: 1 | Y13: COMPLETED | AA13: White glazing | AB13: ±1400mm | AC13: 45822 | AD13: 24 | AE13: POPV260104067 | AF13: 371008611 | AG13: SHANGHAI | AH13: KLAIPEDA | AI13: 45828 | AJ13: 45828 | AK13: 45828 | AL13: 45883 | AM13: 45879 | AN13: 45883 | AO13: CIP | AP13: TIHAMA 525W | AR13: 46010657 | AS13: 254738544 | AT13: 254738544 | AU13: 56 | AV13: Y | AW13: 5 | AX13: 61 | AY13: 45828 | AZ13: 45883 | BA13: #N/A | BC13: 45897 | BD13: 2025 | BE13: 8 | BF13: 35 | BG13: 36 | BH13: 792
A14: MAY014.01 | B14: Yixing | C14: MAY014 | D14: CORE DG | E14: n/a | F14: n/a | H14: DAP | I14: SPIT/ TEST SRL | J14: n/a | K14: 19143069 | L14: Italy & Adriatics Region | M14: n/a | O14: Check Availability in New Ark | P14: Half Cut | Q14: GF0101010094 | R14: 554244 | S14: HSM-ND66-GR615 | T14: 615 | U14: 720 | V14: 0.4428 | W14: 20 | X14: 1 | Y14: COMPLETED | AA14: White glazing | AB14: ±1200mm | AC14: 45817 | AD14: 24 | AE14: POPV251231064 | AF14: 371008567 | AG14: SHANGHAI | AH14: GENOA | AI14: 45821 | AJ14: 45821 | AK14: 45821 | AL14: 45877 | AM14: 45872 | AN14: 45877 | AO14: DAP | AP14: EVER GENTLE/0704-025W | AR14: TPVB20250529006 | AS14: COSU6420591050 | AT14: COSU6420591050 | AU14: 57 | AV14: SWB | AW14: 3 | AX14: 60 | AY14: 45821 | AZ14: 45877 | BA14: #N/A | BC14: 45891 | BD14: 2025 | BE14: 8 | BF14: 34 | BG14: 36 | BH14: 720
A15: MAY014.02 | B15: Yixing | C15: MAY014 | D15: CORE DG | E15: n/a | F15: n/a | H15: CIF | I15: LM Eight | J15: n/a | L15: Iberia Region | M15: n/a | O15: Not Available | P15: Half Cut | Q15: GF0101010094 | R15: 554244 | S15: HSM-ND66-GR615 | T15: 615 | U15: 2880 | V15: 1.7712 | W15: 80 | X15: 4 | Y15: COMPLETED | AA15: White glazing | AB15: ±1200mm | AC15: 45820 | AD15: 24 | AE15: n/a - 2025 legacy | AF15: TPVO2025053014 | AG15: SHANGHAI | AH15: VALENCIA | AI15: 45825 | AJ15: 45825 | AK15: 45825 | AL15: 45869 | AM15: 45869 | AN15: 45869 | AO15: CIF | AP15: COSCO SHIPPING HIMALAYAS/044W | AR15: TPVB20250605003 | AS15: COSU6420290820 | AT15: COSU6420290820 | AU15: 45 | AV15: Y | AW15: 3 | AX15: 49 | AY15: 45825 | AZ15: 45869 | BA15: #N/A | BC15: 45883 | BD15: 2025 | BE15: 8 | BF15: 33 | BG15: 36 | BH15: 720
A16: MAY015.01 | C16: MAY015 | D16: CORE DG | E16: n/a | F16: n/a | H16: DAP | I16: Local WH - SPIT W82 | J16: n/a | L16: Italy & Adriatics Region | M16: n/a | O16: Check Availability in New Ark | P16: Half Cut | Q16: GF0101010095 | R16: 554245 | S16: HSM-ND66-GR620 | T16: 620 | U16: 3600 | V16: 2.232 | W16: 100 | X16: 5 | Y16: COMPLETED | AA16: White glazing | AB16: ±1200mm | AC16: 45823 | AD16: 24 | AE16: POPV251231073 | AF16: 371008568 | AG16: SHANGHAI | AH16: NAPLES | AI16: 45831 | AJ16: 45831 | AK16: 45831 | AL16: 45878 | AM16: 45878 | AN16: 45878 | AO16: DAP | AP16: COSCO SHIPPING SOLAR/033W | AR16: TPVB20250605002 | AS16: COSU6420264270 | AT16: COSU6420264270 | AU16: 48 | AV16: SWB | AW16: 8 | AX16: 55 | AY16: 45831 | AZ16: 45878 | BA16: #N/A | BC16: 45892 | BD16: 2025 | BE16: 8 | BF16: 34 | BG16: 36 | BH16: 720
A17: MAY015.02 | C17: MAY015 | D17: CORE DG | E17: n/a | F17: n/a | H17: CIF | I17: LM Eight | J17: n/a | L17: Iberia Region | M17: n/a | O17: Not Available | P17: Half Cut | Q17: GF0101010095 | R17: 554245 | S17: HSM-ND66-GR620 | T17: 620 | U17: 2880 | V17: 1.7856 | W17: 80 | X17: 4 | Y17: COMPLETED | AA17: White glazing | AB17: ±1200mm | AC17: 45820 | AD17: 24 | AE17: n/a - 2025 legacy | AF17: TPVO2025053014 | AG17: SHANGHAI | AH17: VALENCIA | AI17: 45825 | AJ17: 45825 | AK17: 45825 | AL17: 45869 | AM17: 45869 | AN17: 45869 | AO17: CIF | AP17: COSCO SHIPPING HIMALAYAS/044W | AR17: TPVB20250605003 | AS17: COSU6420290820 | AT17: COSU6420290820 | AU17: 45 | AV17: Y | AW17: 8 | AX17: 49 | AY17: 45825 | AZ17: 45869 | BA17: #N/A | BC17: 45883 | BD17: 2025 | BE17: 8 | BF17: 33 | BG17: 36 | BH17: 720
A18: MAY010.02 | B18: Yixing | C18: MAY010 | D18: CORE DG | E18: n/a | F18: n/a | H18: DAP | I18: Eurologic Sp. Z o.o. | J18: n/a | L18: Emerging Market | M18: n/a | O18: Check Availability in New Ark | P18: Shingle | Q18: GF0700000024 | R18: 554433 | S18: TCL-MR510DT182-64NS | T18: 510 | U18: 2124 | V18: 1.08324 | W18: 59 | X18: 2.6818182 | Y18: COMPLETED | AA18: White glazing | AB18: ±1400mm | AC18: 45830 | AD18: 25 | AE18: POPV251231087 | AF18: 371008577 | AG18: SHANGHAI | AH18: GDANSK | AI18: 45835 | AJ18: 45835 | AK18: 45835 | AL18: 45883 | AM18: 45881 | AN18: 45883 | AO18: DAP | AP18: MANILA EXPRESS/526W | AR18: 46010671 | AS18: MAEU254941683 | AT18: 254941683 | AU18: 49 | AV18: SWB | AW18: 1 | AX18: 53 | AY18: 45835 | AZ18: 45883 | BA18: #N/A | BC18: 45897 | BD18: 2025 | BE18: 8 | BF18: 35 | BG18: 36 | BH18: 792
A19: MAY006.22 | C19: MAY006 | D19: CORE DG | E19: Internal | F19: Arrival Plan-SPTN | G19: SunPower Energy Solutions France SAS | H19: DAP | I19: Local WH | J19: n/a | L19: All | M19: n/a | O19: Check Availability in New Ark | P19: P7 COM S BF IT | Q19: GF0700000769 | R19: 552045 | S19: PVM, SPR-P7-555-COM-S, I BF-G M4.3D EVO2Z6NL 1.5KV IT | T19: 555 | U19: 660 | V19: 0.3663 | W19: 20 | X19: 1 | Y19: COMPLETED | AA19: White glazing | AB19: ±1400mm | AC19: 45826 | AD19: 25 | AE19: POPV251231082 | AF19: 371008584 | AG19: SHANGHAI | AH19: FOS SUR MER | AI19: 45842 | AJ19: 45842 | AK19: 45842 | AL19: 45896 | AM19: 45895 | AN19: 45896 | AO19: DAP | AP19: OOCL HONG KONG 036W | AR19: TPVB20250612001 | AS19: COSU6421224540 | AT19: COSU6421224540_x000D_ | AU19: 55 | AV19: SWB | AW19: 11 | AX19: 70 | AY19: 45842 | AZ19: 45896 | BA19: #N/A | BC19: 45910 | BD19: 2025 | BE19: 9 | BF19: 37 | BG19: 33 | BH19: 660
A20: MAY006.23 | C20: MAY006 | D20: CORE DG | E20: n/a | F20: n/a | H20: DAP | I20: Local WH - SPIT W81 | J20: n/a | L20: Italy & Adriatics Region | M20: n/a | O20: Check Availability in New Ark | P20: P7 COM S BF IT | Q20: GF0700000769 | R20: 552045 | S20: PVM, SPR-P7-555-COM-S, I BF-G M4.3D EVO2Z6NL 1.5KV IT | T20: 555 | U20: 3300 | V20: 1.8315 | W20: 100 | X20: 5 | Y20: COMPLETED | AA20: White glazing | AB20: ±1400mm | AC20: 45830 | AD20: 25 | AE20: POPV251231007 | AF20: 371008585 | AG20: SHANGHAI | AH20: GENOA | AI20: 45842 | AJ20: 45842 | AK20: 45842 | AL20: 45892 | AM20: 45891 | AN20: 45892 | AO20: DAP | AP20: OOCL HONG KONG 036W | AR20: TPVB20250612002 | AS20: COSU6421224760 | AT20: COSU6421224760 | AU20: 51 | AV20: SWB | AW20: 11 | AX20: 62 | AY20: 45842 | AZ20: 45892 | BA20: #N/A | BC20: 45906 | BD20: 2025 | BE20: 9 | BF20: 36 | BG20: 33 | BH20: 660
A21: MAY006.24 | C21: MAY006 | D21: CORE DG | E21: n/a | F21: n/a | H21: DAP | I21: Local WH - SPIT W82 | J21: n/a | L21: Italy & Adriatics Region | M21: n/a | O21: Check Availability in New Ark | P21: P7 COM S BF IT | Q21: GF0700000769 | R21: 552045 | S21: PVM, SPR-P7-555-COM-S, I BF-G M4.3D EVO2Z6NL 1.5KV IT | T21: 555 | U21: 1320 | V21: 0.7326 | W21: 40 | X21: 2 | Y21: COMPLETED | AA21: White glazing | AB21: ±1400mm | AC21: 45826 | AD21: 25 | AE21: POPV251231077 | AF21: 371008586 | AG21: SHANGHAI | AH21: NAPLES | AI21: 45842 | AJ21: 45842 | AK21: 45842 | AL21: 45892 | AM21: 45893 | AN21: 45892 | AO21: DAP | AP21: OOCL HONG KONG 036W | AR21: TPVB20250612003 | AS21: COSU6421224890 | AT21: COSU6421224890_x000D_ | AU21: 51 | AV21: SWB | AW21: 11 | AX21: 66 | AY21: 45842 | AZ21: 45892 | BA21: #N/A | BC21: 45906 | BD21: 2025 | BE21: 9 | BF21: 36 | BG21: 33 | BH21: 660
A22: MAY006.25 | C22: MAY006 | D22: CORE DG | E22: n/a | F22: n/a | H22: DAP | I22: Local WH | J22: n/a | L22: lberia Region | M22: n/a | O22: Check Availability in New Ark | P22: P7 COM S BF IT | Q22: GF0700000769 | R22: 552045 | S22: PVM, SPR-P7-555-COM-S, I BF-G M4.3D EVO2Z6NL 1.5KV IT | T22: 555 | U22: 660 | V22: 0.3663 | W22: 20 | X22: 1 | Y22: COMPLETED | AA22: White glazing | AB22: ±1400mm | AC22: 45826 | AD22: 25 | AE22: POPV251231006 | AF22: 371008587 | AG22: SHANGHAI | AH22: VALENCIA | AI22: 45835 | AJ22: 45835 | AK22: 45835 | AL22: 45882 | AM22: 45882 | AN22: 45882 | AO22: DAP | AP22: CSCL SATURN/085W | AR22: TPVB20250612004 | AS22: COSU6421712120 | AT22: COSU6421712120 | AU22: 48 | AV22: SWB | AW22: 11 | AX22: 56 | AY22: 45835 | AZ22: 45882 | BA22: #N/A | BC22: 45896 | BD22: 2025 | BE22: 8 | BF22: 35 | BG22: 33 | BH22: 660
A23: MAY005.10 | C23: MAY005 | D23: CORE DG | E23: Internal | F23: Arrival Plan-SPTN | G23: SunPower Energy Solutions France SAS | H23: DAP | I23: Local WH | J23: n/a | L23: All | M23: n/a | O23: Check Availability in New Ark | P23: P7 COM S BF IT | Q23: GF0700000766 | R23: 552026 | S23: PVM, SPR-P7-550-COM-S, I BF-G M4.3D EVO2Z6NL 1.5KV IT | T23: 550 | U23: 2640 | V23: 1.452 | W23: 80 | X23: 4 | Y23: COMPLETED | AA23: White glazing | AB23: ±1500mm | AC23: 45826 | AD23: 25 | AE23: POPV251231094 | AF23: 371008581 | AG23: SHANGHAI | AH23: FOS SUR MER | AI23: 45842 | AJ23: 45842 | AK23: 45842 | AL23: 45896 | AM23: 45895 | AN23: 45896 | AO23: DAP | AP23: OOCL HONG KONG 036W | AR23: TPVB20250612001 | AS23: COSU6421224540 | AT23: COSU6421224540 | AU23: 55 | AV23: SWB | AW23: 3 | AX23: 70 | AY23: 45842 | AZ23: 45896 | BA23: #N/A | BC23: 45910 | BD23: 2025 | BE23: 9 | BF23: 37 | BG23: 33 | BH23: 660
A24: MAY005.11 | C24: MAY005 | D24: CORE DG | E24: n/a | F24: n/a | H24: DAP | I24: Local WH - SPIT W81 | J24: n/a | L24: Italy & Adriatics Region | M24: n/a | O24: Check Availability in New Ark | P24: P7 COM S BF IT | Q24: GF0700000766 | R24: 552026 | S24: PVM, SPR-P7-550-COM-S, I BF-G M4.3D EVO2Z6NL 1.5KV IT | T24: 550 | U24: 1320 | V24: 0.726 | W24: 40 | X24: 2 | Y24: COMPLETED | AA24: White glazing | AB24: ±1500mm | AC24: 45830 | AD24: 25 | AE24: POPV251231092 | AF24: 371008582 | AG24: SHANGHAI | AH24: GENOA | AI24: 45842 | AJ24: 45842 | AK24: 45842 | AL24: 45892 | AM24: 45891 | AN24: 45892 | AO24: DAP | AP24: OOCL HONG KONG 036W | AR24: TPVB20250612002 | AS24: COSU6421224760 | AT24: COSU6421224760 | AU24: 51 | AV24: SWB | AW24: 3 | AX24: 62 | AY24: 45842 | AZ24: 45892 | BA24: #N/A | BC24: 45906 | BD24: 2025 | BE24: 9 | BF24: 36 | BG24: 33 | BH24: 660
A25: MAY005.12 | C25: MAY005 | D25: CORE DG | E25: n/a | F25: n/a | H25: DAP | I25: Local WH - SPIT W82 | J25: n/a | L25: Italy & Adriatics Region | M25: n/a | O25: Check Availability in New Ark | P25: P7 COM S BF IT | Q25: GF0700000766 | R25: 552026 | S25: PVM, SPR-P7-550-COM-S, I BF-G M4.3D EVO2Z6NL 1.5KV IT | T25: 550 | U25: 1320 | V25: 0.726 | W25: 40 | X25: 2 | Y25: COMPLETED | AA25: White glazing | AB25: ±1500mm | AC25: 45826 | AD25: 25 | AE25: POPV251231093 | AF25: 371008583 | AG25: SHANGHAI | AH25: NAPLES | AI25: 45842 | AJ25: 45842 | AK25: 45842 | AL25: 45892 | AM25: 45893 | AN25: 45892 | AO25: DAP | AP25: OOCL HONG KONG 036W | AR25: TPVB20250612003 | AS25: COSU6421224890 | AT25: COSU6421224890 | AU25: 51 | AV25: SWB | AW25: 3 | AX25: 66 | AY25: 45842 | AZ25: 45892 | BA25: #N/A | BC25: 45906 | BD25: 2025 | BE25: 9 | BF25: 36 | BG25: 33 | BH25: 660
A26: MAY005 | C26: Main Line | D26: CORE DG | E26: n/a | F26: n/a | H26: DAP | I26: Local WH - SPIT W81 | J26: n/a | L26: Italy & Adriatics Region | M26: n/a | O26: Check Availability in New Ark | P26: P7 COM S BF IT | Q26: GF0700000766 | R26: 552026 | S26: PVM, SPR-P7-550-COM-S, I BF-G M4.3D EVO2Z6NL 1.5KV IT | T26: 550 | U26: 3300 | V26: 1.815 | W26: 100 | X26: 5 | Y26: COMPLETED | AA26: White glazing | AB26: ±1500mm | AC26: 45836 | AD26: 26 | AE26: POPV251231005 | AF26: 371008616 | AG26: SHANGHAI | AH26: GENOA | AI26: 45847 | AJ26: 45847 | AK26: 45847 | AL26: 45903 | AM26: 45900 | AN26: 45903 | AO26: DAP | AP26: EVER GRADE 0707-025W | AR26: TPVB20250619002 | AS26: COSU6422739630 | AT26: COSU6422739630 | AU26: 57 | AV26: SWB | AW26: 39 | AX26: 67 | AY26: 45847 | AZ26: 45903 | BA26: #N/A | BC26: 45917 | BD26: 2025 | BE26: 9 | BF26: 38 | BG26: 33 | BH26: 660
A27: MAY015.03 | B27: Lianyungang | C27: MAY015 | D27: CORE DG | E27: n/a | F27: n/a | H27: FOB | I27: UAB Elmitra | J27: n/a | L27: Emerging Market | M27: n/a | O27: Check Availability in New Ark | P27: Half Cut | Q27: GF0101010095 | R27: 554245 | S27: HSM-ND66-GR620 | T27: 620 | U27: 720 | V27: 0.4464 | W27: 20 | X27: 1 | Y27: COMPLETED | AA27: White glazing | AB27: ±1200mm | AC27: 45831 | AD27: 26 | AE27: POPV260104111 | AF27: 371008612 | AG27: SHANGHAI | AH27: KLAIPEDA | AI27: 45846 | AJ27: 45846 | AK27: 45846 | AL27: 45900 | AN27: 45900 | AO27: FOB | AP27: MSC ALESSIA QB526W | AR27: 46010646 | AS27: 1067418014 | AT27: 177FVKVKS234167 | AU27: 55 | AV27: Y | AW27: 8 | AX27: 69 | AY27: 45846 | AZ27: 45900 | BA27: #N/A | BC27: 45914 | BD27: 2025 | BE27: 9 | BF27: 37 | BG27: 36 | BH27: 720
A28: MAY015.04 | C28: MAY015 | D28: CORE DG | E28: n/a | F28: n/a | H28: DAP | I28: Italy Distrib. | J28: n/a | L28: Italy & Adriatics Region | M28: n/a | O28: Check Availability in New Ark | P28: Half Cut | Q28: GF0101010095 | R28: 554245 | S28: HSM-ND66-GR620 | T28: 620 | U28: 720 | V28: 0.4464 | W28: 20 | X28: 1 | Y28: COMPLETED | AA28: White glazing | AB28: ±1200mm | AC28: 45835 | AD28: 26 | AE28: POPV251231088 | AF28: 371008619 | AG28: SHANGHAI | AH28: GENOA | AI28: 45847 | AJ28: 45847 | AK28: 45847 | AL28: 45903 | AM28: 45900 | AN28: 45903 | AO28: DAP | AP28: EVER GRADE 0707-025W | AR28: TPVB20250619001 | AS28: COSU6421953700 | AT28: COSU6421953700 | AU28: 57 | AV28: SWB | AW28: 8 | AX28: 68 | AY28: 45847 | AZ28: 45903 | BA28: #N/A | BC28: 45917 | BD28: 2025 | BE28: 9 | BF28: 38 | BG28: 36 | BH28: 720
